{
  "cells": [
    {
      "cell_type": "markdown",
      "metadata": {
        "id": "view-in-github",
        "colab_type": "text"
      },
      "source": [
        "<a href=\"https://colab.research.google.com/github/boyzhu/RcTorch/blob/master/train_lnn_stock_public.ipynb\" target=\"_parent\"><img src=\"https://colab.research.google.com/assets/colab-badge.svg\" alt=\"Open In Colab\"/></a>"
      ]
    },
    {
      "cell_type": "markdown",
      "source": [
        "Tensorflow version >= 2.16 doesn`t support AbstractRNNCell, so we need to downgrade to 2.15.1"
      ],
      "metadata": {
        "id": "1L-mpnRJpvGS"
      }
    },
    {
      "cell_type": "code",
      "source": [
        "pip install --upgrade tensorflow==2.15.1"
      ],
      "metadata": {
        "colab": {
          "base_uri": "https://localhost:8080/",
          "height": 1000
        },
        "id": "8nXyruBbpsZz",
        "outputId": "3d70bfda-dd8f-4ecf-b218-37e7cd3c469d",
        "collapsed": true
      },
      "execution_count": 2,
      "outputs": [
        {
          "output_type": "stream",
          "name": "stderr",
          "text": [
            "ERROR:root:Unexpected exception finding object shape\n",
            "Traceback (most recent call last):\n",
            "  File \"/usr/local/lib/python3.11/dist-packages/google/colab/_debugpy_repr.py\", line 54, in get_shape\n",
            "    shape = getattr(obj, 'shape', None)\n",
            "            ^^^^^^^^^^^^^^^^^^^^^^^^^^^\n",
            "  File \"/usr/local/lib/python3.11/dist-packages/werkzeug/local.py\", line 318, in __get__\n",
            "    obj = instance._get_current_object()\n",
            "          ^^^^^^^^^^^^^^^^^^^^^^^^^^^^^^\n",
            "  File \"/usr/local/lib/python3.11/dist-packages/werkzeug/local.py\", line 519, in _get_current_object\n",
            "    raise RuntimeError(unbound_message) from None\n",
            "RuntimeError: Working outside of request context.\n",
            "\n",
            "This typically means that you attempted to use functionality that needed\n",
            "an active HTTP request. Consult the documentation on testing for\n",
            "information about how to avoid this problem.\n"
          ]
        },
        {
          "output_type": "stream",
          "name": "stdout",
          "text": [
            "Collecting tensorflow==2.15.1\n",
            "  Downloading tensorflow-2.15.1-cp311-cp311-manylinux_2_17_x86_64.manylinux2014_x86_64.whl.metadata (4.2 kB)\n",
            "Requirement already satisfied: absl-py>=1.0.0 in /usr/local/lib/python3.11/dist-packages (from tensorflow==2.15.1) (1.4.0)\n",
            "Requirement already satisfied: astunparse>=1.6.0 in /usr/local/lib/python3.11/dist-packages (from tensorflow==2.15.1) (1.6.3)\n",
            "Requirement already satisfied: flatbuffers>=23.5.26 in /usr/local/lib/python3.11/dist-packages (from tensorflow==2.15.1) (25.2.10)\n",
            "Requirement already satisfied: gast!=0.5.0,!=0.5.1,!=0.5.2,>=0.2.1 in /usr/local/lib/python3.11/dist-packages (from tensorflow==2.15.1) (0.6.0)\n",
            "Requirement already satisfied: google-pasta>=0.1.1 in /usr/local/lib/python3.11/dist-packages (from tensorflow==2.15.1) (0.2.0)\n",
            "Requirement already satisfied: h5py>=2.9.0 in /usr/local/lib/python3.11/dist-packages (from tensorflow==2.15.1) (3.12.1)\n",
            "Requirement already satisfied: libclang>=13.0.0 in /usr/local/lib/python3.11/dist-packages (from tensorflow==2.15.1) (18.1.1)\n",
            "Collecting ml-dtypes~=0.3.1 (from tensorflow==2.15.1)\n",
            "  Downloading ml_dtypes-0.3.2-cp311-cp311-manylinux_2_17_x86_64.manylinux2014_x86_64.whl.metadata (20 kB)\n",
            "Requirement already satisfied: numpy<2.0.0,>=1.23.5 in /usr/local/lib/python3.11/dist-packages (from tensorflow==2.15.1) (1.26.4)\n",
            "Requirement already satisfied: opt-einsum>=2.3.2 in /usr/local/lib/python3.11/dist-packages (from tensorflow==2.15.1) (3.4.0)\n",
            "Requirement already satisfied: packaging in /usr/local/lib/python3.11/dist-packages (from tensorflow==2.15.1) (24.2)\n",
            "Requirement already satisfied: protobuf!=4.21.0,!=4.21.1,!=4.21.2,!=4.21.3,!=4.21.4,!=4.21.5,<5.0.0dev,>=3.20.3 in /usr/local/lib/python3.11/dist-packages (from tensorflow==2.15.1) (4.25.6)\n",
            "Requirement already satisfied: setuptools in /usr/local/lib/python3.11/dist-packages (from tensorflow==2.15.1) (75.1.0)\n",
            "Requirement already satisfied: six>=1.12.0 in /usr/local/lib/python3.11/dist-packages (from tensorflow==2.15.1) (1.17.0)\n",
            "Requirement already satisfied: termcolor>=1.1.0 in /usr/local/lib/python3.11/dist-packages (from tensorflow==2.15.1) (2.5.0)\n",
            "Requirement already satisfied: typing-extensions>=3.6.6 in /usr/local/lib/python3.11/dist-packages (from tensorflow==2.15.1) (4.12.2)\n"
          ]
        },
        {
          "output_type": "stream",
          "name": "stderr",
          "text": [
            "ERROR:root:Unexpected exception finding object shape\n",
            "Traceback (most recent call last):\n",
            "  File \"/usr/local/lib/python3.11/dist-packages/google/colab/_debugpy_repr.py\", line 54, in get_shape\n",
            "    shape = getattr(obj, 'shape', None)\n",
            "            ^^^^^^^^^^^^^^^^^^^^^^^^^^^\n",
            "  File \"/usr/local/lib/python3.11/dist-packages/werkzeug/local.py\", line 318, in __get__\n",
            "    obj = instance._get_current_object()\n",
            "          ^^^^^^^^^^^^^^^^^^^^^^^^^^^^^^\n",
            "  File \"/usr/local/lib/python3.11/dist-packages/werkzeug/local.py\", line 519, in _get_current_object\n",
            "    raise RuntimeError(unbound_message) from None\n",
            "RuntimeError: Working outside of request context.\n",
            "\n",
            "This typically means that you attempted to use functionality that needed\n",
            "an active HTTP request. Consult the documentation on testing for\n",
            "information about how to avoid this problem.\n"
          ]
        },
        {
          "output_type": "stream",
          "name": "stdout",
          "text": [
            "Collecting wrapt<1.15,>=1.11.0 (from tensorflow==2.15.1)\n",
            "  Downloading wrapt-1.14.1-cp311-cp311-manylinux_2_5_x86_64.manylinux1_x86_64.manylinux_2_17_x86_64.manylinux2014_x86_64.whl.metadata (6.7 kB)\n",
            "Requirement already satisfied: tensorflow-io-gcs-filesystem>=0.23.1 in /usr/local/lib/python3.11/dist-packages (from tensorflow==2.15.1) (0.37.1)\n",
            "Requirement already satisfied: grpcio<2.0,>=1.24.3 in /usr/local/lib/python3.11/dist-packages (from tensorflow==2.15.1) (1.70.0)\n",
            "Collecting tensorboard<2.16,>=2.15 (from tensorflow==2.15.1)\n",
            "  Downloading tensorboard-2.15.2-py3-none-any.whl.metadata (1.7 kB)\n",
            "Collecting tensorflow-estimator<2.16,>=2.15.0 (from tensorflow==2.15.1)\n",
            "  Downloading tensorflow_estimator-2.15.0-py2.py3-none-any.whl.metadata (1.3 kB)\n",
            "Collecting keras<2.16,>=2.15.0 (from tensorflow==2.15.1)\n"
          ]
        },
        {
          "output_type": "stream",
          "name": "stderr",
          "text": [
            "ERROR:root:Unexpected exception finding object shape\n",
            "Traceback (most recent call last):\n",
            "  File \"/usr/local/lib/python3.11/dist-packages/google/colab/_debugpy_repr.py\", line 54, in get_shape\n",
            "    shape = getattr(obj, 'shape', None)\n",
            "            ^^^^^^^^^^^^^^^^^^^^^^^^^^^\n",
            "  File \"/usr/local/lib/python3.11/dist-packages/werkzeug/local.py\", line 318, in __get__\n",
            "    obj = instance._get_current_object()\n",
            "          ^^^^^^^^^^^^^^^^^^^^^^^^^^^^^^\n",
            "  File \"/usr/local/lib/python3.11/dist-packages/werkzeug/local.py\", line 519, in _get_current_object\n",
            "    raise RuntimeError(unbound_message) from None\n",
            "RuntimeError: Working outside of request context.\n",
            "\n",
            "This typically means that you attempted to use functionality that needed\n",
            "an active HTTP request. Consult the documentation on testing for\n",
            "information about how to avoid this problem.\n"
          ]
        },
        {
          "output_type": "stream",
          "name": "stdout",
          "text": [
            "  Downloading keras-2.15.0-py3-none-any.whl.metadata (2.4 kB)\n",
            "Requirement already satisfied: wheel<1.0,>=0.23.0 in /usr/local/lib/python3.11/dist-packages (from astunparse>=1.6.0->tensorflow==2.15.1) (0.45.1)\n",
            "Requirement already satisfied: google-auth<3,>=1.6.3 in /usr/local/lib/python3.11/dist-packages (from tensorboard<2.16,>=2.15->tensorflow==2.15.1) (2.38.0)\n",
            "Requirement already satisfied: google-auth-oauthlib<2,>=0.5 in /usr/local/lib/python3.11/dist-packages (from tensorboard<2.16,>=2.15->tensorflow==2.15.1) (1.2.1)\n",
            "Requirement already satisfied: markdown>=2.6.8 in /usr/local/lib/python3.11/dist-packages (from tensorboard<2.16,>=2.15->tensorflow==2.15.1) (3.7)\n",
            "Requirement already satisfied: requests<3,>=2.21.0 in /usr/local/lib/python3.11/dist-packages (from tensorboard<2.16,>=2.15->tensorflow==2.15.1) (2.32.3)\n",
            "Requirement already satisfied: tensorboard-data-server<0.8.0,>=0.7.0 in /usr/local/lib/python3.11/dist-packages (from tensorboard<2.16,>=2.15->tensorflow==2.15.1) (0.7.2)\n",
            "Requirement already satisfied: werkzeug>=1.0.1 in /usr/local/lib/python3.11/dist-packages (from tensorboard<2.16,>=2.15->tensorflow==2.15.1) (3.1.3)\n",
            "Requirement already satisfied: cachetools<6.0,>=2.0.0 in /usr/local/lib/python3.11/dist-packages (from google-auth<3,>=1.6.3->tensorboard<2.16,>=2.15->tensorflow==2.15.1) (5.5.2)\n",
            "Requirement already satisfied: pyasn1-modules>=0.2.1 in /usr/local/lib/python3.11/dist-packages (from google-auth<3,>=1.6.3->tensorboard<2.16,>=2.15->tensorflow==2.15.1) (0.4.1)\n",
            "Requirement already satisfied: rsa<5,>=3.1.4 in /usr/local/lib/python3.11/dist-packages (from google-auth<3,>=1.6.3->tensorboard<2.16,>=2.15->tensorflow==2.15.1) (4.9)\n",
            "Requirement already satisfied: requests-oauthlib>=0.7.0 in /usr/local/lib/python3.11/dist-packages (from google-auth-oauthlib<2,>=0.5->tensorboard<2.16,>=2.15->tensorflow==2.15.1) (2.0.0)\n",
            "Requirement already satisfied: charset-normalizer<4,>=2 in /usr/local/lib/python3.11/dist-packages (from requests<3,>=2.21.0->tensorboard<2.16,>=2.15->tensorflow==2.15.1) (3.4.1)\n",
            "Requirement already satisfied: idna<4,>=2.5 in /usr/local/lib/python3.11/dist-packages (from requests<3,>=2.21.0->tensorboard<2.16,>=2.15->tensorflow==2.15.1) (3.10)\n",
            "Requirement already satisfied: urllib3<3,>=1.21.1 in /usr/local/lib/python3.11/dist-packages (from requests<3,>=2.21.0->tensorboard<2.16,>=2.15->tensorflow==2.15.1) (2.3.0)\n",
            "Requirement already satisfied: certifi>=2017.4.17 in /usr/local/lib/python3.11/dist-packages (from requests<3,>=2.21.0->tensorboard<2.16,>=2.15->tensorflow==2.15.1) (2025.1.31)\n",
            "Requirement already satisfied: MarkupSafe>=2.1.1 in /usr/local/lib/python3.11/dist-packages (from werkzeug>=1.0.1->tensorboard<2.16,>=2.15->tensorflow==2.15.1) (3.0.2)\n",
            "Requirement already satisfied: pyasn1<0.7.0,>=0.4.6 in /usr/local/lib/python3.11/dist-packages (from pyasn1-modules>=0.2.1->google-auth<3,>=1.6.3->tensorboard<2.16,>=2.15->tensorflow==2.15.1) (0.6.1)\n",
            "Requirement already satisfied: oauthlib>=3.0.0 in /usr/local/lib/python3.11/dist-packages (from requests-oauthlib>=0.7.0->google-auth-oauthlib<2,>=0.5->tensorboard<2.16,>=2.15->tensorflow==2.15.1) (3.2.2)\n",
            "Downloading tensorflow-2.15.1-cp311-cp311-manylinux_2_17_x86_64.manylinux2014_x86_64.whl (475.3 MB)\n",
            "\u001b[2K   \u001b[91m━━━━━━━━━━━━━\u001b[0m\u001b[91m╸\u001b[0m\u001b[90m━━━━━━━━━━━━━━━━━━━━━━━━━━\u001b[0m \u001b[32m162.2/475.3 MB\u001b[0m \u001b[31m43.1 MB/s\u001b[0m eta \u001b[36m0:00:08\u001b[0m"
          ]
        },
        {
          "output_type": "stream",
          "name": "stderr",
          "text": [
            "ERROR:root:Unexpected exception finding object shape\n",
            "Traceback (most recent call last):\n",
            "  File \"/usr/local/lib/python3.11/dist-packages/google/colab/_debugpy_repr.py\", line 54, in get_shape\n",
            "    shape = getattr(obj, 'shape', None)\n",
            "            ^^^^^^^^^^^^^^^^^^^^^^^^^^^\n",
            "  File \"/usr/local/lib/python3.11/dist-packages/werkzeug/local.py\", line 318, in __get__\n",
            "    obj = instance._get_current_object()\n",
            "          ^^^^^^^^^^^^^^^^^^^^^^^^^^^^^^\n",
            "  File \"/usr/local/lib/python3.11/dist-packages/werkzeug/local.py\", line 519, in _get_current_object\n",
            "    raise RuntimeError(unbound_message) from None\n",
            "RuntimeError: Working outside of request context.\n",
            "\n",
            "This typically means that you attempted to use functionality that needed\n",
            "an active HTTP request. Consult the documentation on testing for\n",
            "information about how to avoid this problem.\n"
          ]
        },
        {
          "output_type": "stream",
          "name": "stdout",
          "text": [
            "\u001b[2K   \u001b[91m━━━━━━━━━━━━━\u001b[0m\u001b[91m╸\u001b[0m\u001b[90m━━━━━━━━━━━━━━━━━━━━━━━━━━\u001b[0m \u001b[32m162.6/475.3 MB\u001b[0m \u001b[31m14.1 MB/s\u001b[0m eta \u001b[36m0:00:23\u001b[0m"
          ]
        },
        {
          "output_type": "stream",
          "name": "stderr",
          "text": [
            "ERROR:root:Unexpected exception finding object shape\n",
            "Traceback (most recent call last):\n",
            "  File \"/usr/local/lib/python3.11/dist-packages/google/colab/_debugpy_repr.py\", line 54, in get_shape\n",
            "    shape = getattr(obj, 'shape', None)\n",
            "            ^^^^^^^^^^^^^^^^^^^^^^^^^^^\n",
            "  File \"/usr/local/lib/python3.11/dist-packages/werkzeug/local.py\", line 318, in __get__\n",
            "    obj = instance._get_current_object()\n",
            "          ^^^^^^^^^^^^^^^^^^^^^^^^^^^^^^\n",
            "  File \"/usr/local/lib/python3.11/dist-packages/werkzeug/local.py\", line 519, in _get_current_object\n",
            "    raise RuntimeError(unbound_message) from None\n",
            "RuntimeError: Working outside of request context.\n",
            "\n",
            "This typically means that you attempted to use functionality that needed\n",
            "an active HTTP request. Consult the documentation on testing for\n",
            "information about how to avoid this problem.\n"
          ]
        },
        {
          "output_type": "stream",
          "name": "stdout",
          "text": [
            "\u001b[2K   \u001b[91m━━━━━━━━━━━━━\u001b[0m\u001b[91m╸\u001b[0m\u001b[90m━━━━━━━━━━━━━━━━━━━━━━━━━━\u001b[0m \u001b[32m163.8/475.3 MB\u001b[0m \u001b[31m4.6 MB/s\u001b[0m eta \u001b[36m0:01:09\u001b[0m"
          ]
        },
        {
          "output_type": "stream",
          "name": "stderr",
          "text": [
            "ERROR:root:Unexpected exception finding object shape\n",
            "Traceback (most recent call last):\n",
            "  File \"/usr/local/lib/python3.11/dist-packages/google/colab/_debugpy_repr.py\", line 54, in get_shape\n",
            "    shape = getattr(obj, 'shape', None)\n",
            "            ^^^^^^^^^^^^^^^^^^^^^^^^^^^\n",
            "  File \"/usr/local/lib/python3.11/dist-packages/werkzeug/local.py\", line 318, in __get__\n",
            "    obj = instance._get_current_object()\n",
            "          ^^^^^^^^^^^^^^^^^^^^^^^^^^^^^^\n",
            "  File \"/usr/local/lib/python3.11/dist-packages/werkzeug/local.py\", line 519, in _get_current_object\n",
            "    raise RuntimeError(unbound_message) from None\n",
            "RuntimeError: Working outside of request context.\n",
            "\n",
            "This typically means that you attempted to use functionality that needed\n",
            "an active HTTP request. Consult the documentation on testing for\n",
            "information about how to avoid this problem.\n"
          ]
        },
        {
          "output_type": "stream",
          "name": "stdout",
          "text": [
            "\u001b[2K   \u001b[91m━━━━━━━━━━━━━\u001b[0m\u001b[91m╸\u001b[0m\u001b[90m━━━━━━━━━━━━━━━━━━━━━━━━━━\u001b[0m \u001b[32m164.2/475.3 MB\u001b[0m \u001b[31m3.8 MB/s\u001b[0m eta \u001b[36m0:01:23\u001b[0m"
          ]
        },
        {
          "output_type": "stream",
          "name": "stderr",
          "text": [
            "ERROR:root:Unexpected exception finding object shape\n",
            "Traceback (most recent call last):\n",
            "  File \"/usr/local/lib/python3.11/dist-packages/google/colab/_debugpy_repr.py\", line 54, in get_shape\n",
            "    shape = getattr(obj, 'shape', None)\n",
            "            ^^^^^^^^^^^^^^^^^^^^^^^^^^^\n",
            "  File \"/usr/local/lib/python3.11/dist-packages/werkzeug/local.py\", line 318, in __get__\n",
            "    obj = instance._get_current_object()\n",
            "          ^^^^^^^^^^^^^^^^^^^^^^^^^^^^^^\n",
            "  File \"/usr/local/lib/python3.11/dist-packages/werkzeug/local.py\", line 519, in _get_current_object\n",
            "    raise RuntimeError(unbound_message) from None\n",
            "RuntimeError: Working outside of request context.\n",
            "\n",
            "This typically means that you attempted to use functionality that needed\n",
            "an active HTTP request. Consult the documentation on testing for\n",
            "information about how to avoid this problem.\n"
          ]
        },
        {
          "output_type": "stream",
          "name": "stdout",
          "text": [
            "\u001b[2K   \u001b[91m━━━━━━━━━━━━━━\u001b[0m\u001b[91m╸\u001b[0m\u001b[90m━━━━━━━━━━━━━━━━━━━━━━━━━\u001b[0m \u001b[32m174.6/475.3 MB\u001b[0m \u001b[31m13.2 MB/s\u001b[0m eta \u001b[36m0:00:23\u001b[0m"
          ]
        },
        {
          "output_type": "stream",
          "name": "stderr",
          "text": [
            "ERROR:root:Unexpected exception finding object shape\n",
            "Traceback (most recent call last):\n",
            "  File \"/usr/local/lib/python3.11/dist-packages/google/colab/_debugpy_repr.py\", line 54, in get_shape\n",
            "    shape = getattr(obj, 'shape', None)\n",
            "            ^^^^^^^^^^^^^^^^^^^^^^^^^^^\n",
            "  File \"/usr/local/lib/python3.11/dist-packages/werkzeug/local.py\", line 318, in __get__\n",
            "    obj = instance._get_current_object()\n",
            "          ^^^^^^^^^^^^^^^^^^^^^^^^^^^^^^\n",
            "  File \"/usr/local/lib/python3.11/dist-packages/werkzeug/local.py\", line 519, in _get_current_object\n",
            "    raise RuntimeError(unbound_message) from None\n",
            "RuntimeError: Working outside of request context.\n",
            "\n",
            "This typically means that you attempted to use functionality that needed\n",
            "an active HTTP request. Consult the documentation on testing for\n",
            "information about how to avoid this problem.\n"
          ]
        },
        {
          "output_type": "stream",
          "name": "stdout",
          "text": [
            "\u001b[2K   \u001b[91m━━━━━━━━━━━━━━━━━━\u001b[0m\u001b[90m╺\u001b[0m\u001b[90m━━━━━━━━━━━━━━━━━━━━━\u001b[0m \u001b[32m219.1/475.3 MB\u001b[0m \u001b[31m7.9 MB/s\u001b[0m eta \u001b[36m0:00:33\u001b[0m"
          ]
        },
        {
          "output_type": "stream",
          "name": "stderr",
          "text": [
            "ERROR:root:Unexpected exception finding object shape\n",
            "Traceback (most recent call last):\n",
            "  File \"/usr/local/lib/python3.11/dist-packages/google/colab/_debugpy_repr.py\", line 54, in get_shape\n",
            "    shape = getattr(obj, 'shape', None)\n",
            "            ^^^^^^^^^^^^^^^^^^^^^^^^^^^\n",
            "  File \"/usr/local/lib/python3.11/dist-packages/werkzeug/local.py\", line 318, in __get__\n",
            "    obj = instance._get_current_object()\n",
            "          ^^^^^^^^^^^^^^^^^^^^^^^^^^^^^^\n",
            "  File \"/usr/local/lib/python3.11/dist-packages/werkzeug/local.py\", line 519, in _get_current_object\n",
            "    raise RuntimeError(unbound_message) from None\n",
            "RuntimeError: Working outside of request context.\n",
            "\n",
            "This typically means that you attempted to use functionality that needed\n",
            "an active HTTP request. Consult the documentation on testing for\n",
            "information about how to avoid this problem.\n"
          ]
        },
        {
          "output_type": "stream",
          "name": "stdout",
          "text": [
            "\u001b[2K   \u001b[91m━━━━━━━━━━━━━━━━━━\u001b[0m\u001b[90m╺\u001b[0m\u001b[90m━━━━━━━━━━━━━━━━━━━━━\u001b[0m \u001b[32m219.5/475.3 MB\u001b[0m \u001b[31m5.7 MB/s\u001b[0m eta \u001b[36m0:00:45\u001b[0m"
          ]
        },
        {
          "output_type": "stream",
          "name": "stderr",
          "text": [
            "ERROR:root:Unexpected exception finding object shape\n",
            "Traceback (most recent call last):\n",
            "  File \"/usr/local/lib/python3.11/dist-packages/google/colab/_debugpy_repr.py\", line 54, in get_shape\n",
            "    shape = getattr(obj, 'shape', None)\n",
            "            ^^^^^^^^^^^^^^^^^^^^^^^^^^^\n",
            "  File \"/usr/local/lib/python3.11/dist-packages/werkzeug/local.py\", line 318, in __get__\n",
            "    obj = instance._get_current_object()\n",
            "          ^^^^^^^^^^^^^^^^^^^^^^^^^^^^^^\n",
            "  File \"/usr/local/lib/python3.11/dist-packages/werkzeug/local.py\", line 519, in _get_current_object\n",
            "    raise RuntimeError(unbound_message) from None\n",
            "RuntimeError: Working outside of request context.\n",
            "\n",
            "This typically means that you attempted to use functionality that needed\n",
            "an active HTTP request. Consult the documentation on testing for\n",
            "information about how to avoid this problem.\n"
          ]
        },
        {
          "output_type": "stream",
          "name": "stdout",
          "text": [
            "\u001b[2K   \u001b[91m━━━━━━━━━━━━━━━━━━━━━━━\u001b[0m\u001b[91m╸\u001b[0m\u001b[90m━━━━━━━━━━━━━━━━\u001b[0m \u001b[32m281.6/475.3 MB\u001b[0m \u001b[31m105.3 MB/s\u001b[0m eta \u001b[36m0:00:02\u001b[0m"
          ]
        },
        {
          "output_type": "stream",
          "name": "stderr",
          "text": [
            "ERROR:root:Unexpected exception finding object shape\n",
            "Traceback (most recent call last):\n",
            "  File \"/usr/local/lib/python3.11/dist-packages/google/colab/_debugpy_repr.py\", line 54, in get_shape\n",
            "    shape = getattr(obj, 'shape', None)\n",
            "            ^^^^^^^^^^^^^^^^^^^^^^^^^^^\n",
            "  File \"/usr/local/lib/python3.11/dist-packages/werkzeug/local.py\", line 318, in __get__\n",
            "    obj = instance._get_current_object()\n",
            "          ^^^^^^^^^^^^^^^^^^^^^^^^^^^^^^\n",
            "  File \"/usr/local/lib/python3.11/dist-packages/werkzeug/local.py\", line 519, in _get_current_object\n",
            "    raise RuntimeError(unbound_message) from None\n",
            "RuntimeError: Working outside of request context.\n",
            "\n",
            "This typically means that you attempted to use functionality that needed\n",
            "an active HTTP request. Consult the documentation on testing for\n",
            "information about how to avoid this problem.\n"
          ]
        },
        {
          "output_type": "stream",
          "name": "stdout",
          "text": [
            "\u001b[2K   \u001b[91m━━━━━━━━━━━━━━━━━━━━━━━━━━━━━━━━━━━━━━━\u001b[0m\u001b[91m╸\u001b[0m \u001b[32m475.2/475.3 MB\u001b[0m \u001b[31m99.1 MB/s\u001b[0m eta \u001b[36m0:00:01\u001b[0m"
          ]
        },
        {
          "output_type": "stream",
          "name": "stderr",
          "text": [
            "ERROR:root:Unexpected exception finding object shape\n",
            "Traceback (most recent call last):\n",
            "  File \"/usr/local/lib/python3.11/dist-packages/google/colab/_debugpy_repr.py\", line 54, in get_shape\n",
            "    shape = getattr(obj, 'shape', None)\n",
            "            ^^^^^^^^^^^^^^^^^^^^^^^^^^^\n",
            "  File \"/usr/local/lib/python3.11/dist-packages/werkzeug/local.py\", line 318, in __get__\n",
            "    obj = instance._get_current_object()\n",
            "          ^^^^^^^^^^^^^^^^^^^^^^^^^^^^^^\n",
            "  File \"/usr/local/lib/python3.11/dist-packages/werkzeug/local.py\", line 519, in _get_current_object\n",
            "    raise RuntimeError(unbound_message) from None\n",
            "RuntimeError: Working outside of request context.\n",
            "\n",
            "This typically means that you attempted to use functionality that needed\n",
            "an active HTTP request. Consult the documentation on testing for\n",
            "information about how to avoid this problem.\n"
          ]
        },
        {
          "output_type": "stream",
          "name": "stdout",
          "text": [
            "\u001b[2K   \u001b[91m━━━━━━━━━━━━━━━━━━━━━━━━━━━━━━━━━━━━━━━\u001b[0m\u001b[91m╸\u001b[0m \u001b[32m475.2/475.3 MB\u001b[0m \u001b[31m99.1 MB/s\u001b[0m eta \u001b[36m0:00:01\u001b[0m"
          ]
        },
        {
          "output_type": "stream",
          "name": "stderr",
          "text": [
            "ERROR:root:Unexpected exception finding object shape\n",
            "Traceback (most recent call last):\n",
            "  File \"/usr/local/lib/python3.11/dist-packages/google/colab/_debugpy_repr.py\", line 54, in get_shape\n",
            "    shape = getattr(obj, 'shape', None)\n",
            "            ^^^^^^^^^^^^^^^^^^^^^^^^^^^\n",
            "  File \"/usr/local/lib/python3.11/dist-packages/werkzeug/local.py\", line 318, in __get__\n",
            "    obj = instance._get_current_object()\n",
            "          ^^^^^^^^^^^^^^^^^^^^^^^^^^^^^^\n",
            "  File \"/usr/local/lib/python3.11/dist-packages/werkzeug/local.py\", line 519, in _get_current_object\n",
            "    raise RuntimeError(unbound_message) from None\n",
            "RuntimeError: Working outside of request context.\n",
            "\n",
            "This typically means that you attempted to use functionality that needed\n",
            "an active HTTP request. Consult the documentation on testing for\n",
            "information about how to avoid this problem.\n"
          ]
        },
        {
          "output_type": "stream",
          "name": "stdout",
          "text": [
            "\r\u001b[2K   \u001b[91m━━━━━━━━━━━━━━━━━━━━━━━━━━━━━━━━━━━━━━━\u001b[0m\u001b[91m╸\u001b[0m \u001b[32m475.2/475.3 MB\u001b[0m \u001b[31m99.1 MB/s\u001b[0m eta \u001b[36m0:00:01\u001b[0m\r\u001b[2K   \u001b[91m━━━━━━━━━━━━━━━━━━━━━━━━━━━━━━━━━━━━━━━\u001b[0m\u001b[91m╸\u001b[0m \u001b[32m475.2/475.3 MB\u001b[0m \u001b[31m99.1 MB/s\u001b[0m eta \u001b[36m0:00:01\u001b[0m\r\u001b[2K   \u001b[91m━━━━━━━━━━━━━━━━━━━━━━━━━━━━━━━━━━━━━━━\u001b[0m\u001b[91m╸\u001b[0m \u001b[32m475.2/475.3 MB\u001b[0m \u001b[31m99.1 MB/s\u001b[0m eta \u001b[36m0:00:01\u001b[0m\r\u001b[2K   \u001b[91m━━━━━━━━━━━━━━━━━━━━━━━━━━━━━━━━━━━━━━━\u001b[0m\u001b[91m╸\u001b[0m \u001b[32m475.2/475.3 MB\u001b[0m \u001b[31m99.1 MB/s\u001b[0m eta \u001b[36m0:00:01\u001b[0m\r\u001b[2K   \u001b[91m━━━━━━━━━━━━━━━━━━━━━━━━━━━━━━━━━━━━━━━\u001b[0m\u001b[91m╸\u001b[0m \u001b[32m475.2/475.3 MB\u001b[0m \u001b[31m99.1 MB/s\u001b[0m eta \u001b[36m0:00:01\u001b[0m\r\u001b[2K   \u001b[91m━━━━━━━━━━━━━━━━━━━━━━━━━━━━━━━━━━━━━━━\u001b[0m\u001b[91m╸\u001b[0m \u001b[32m475.2/475.3 MB\u001b[0m \u001b[31m99.1 MB/s\u001b[0m eta \u001b[36m0:00:01\u001b[0m\r\u001b[2K   \u001b[91m━━━━━━━━━━━━━━━━━━━━━━━━━━━━━━━━━━━━━━━\u001b[0m\u001b[91m╸\u001b[0m \u001b[32m475.2/475.3 MB\u001b[0m \u001b[31m99.1 MB/s\u001b[0m eta \u001b[36m0:00:01\u001b[0m\r\u001b[2K   \u001b[91m━━━━━━━━━━━━━━━━━━━━━━━━━━━━━━━━━━━━━━━\u001b[0m\u001b[91m╸\u001b[0m \u001b[32m475.2/475.3 MB\u001b[0m \u001b[31m99.1 MB/s\u001b[0m eta \u001b[36m0:00:01\u001b[0m"
          ]
        },
        {
          "output_type": "stream",
          "name": "stderr",
          "text": [
            "ERROR:root:Unexpected exception finding object shape\n",
            "Traceback (most recent call last):\n",
            "  File \"/usr/local/lib/python3.11/dist-packages/google/colab/_debugpy_repr.py\", line 54, in get_shape\n",
            "    shape = getattr(obj, 'shape', None)\n",
            "            ^^^^^^^^^^^^^^^^^^^^^^^^^^^\n",
            "  File \"/usr/local/lib/python3.11/dist-packages/werkzeug/local.py\", line 318, in __get__\n",
            "    obj = instance._get_current_object()\n",
            "          ^^^^^^^^^^^^^^^^^^^^^^^^^^^^^^\n",
            "  File \"/usr/local/lib/python3.11/dist-packages/werkzeug/local.py\", line 519, in _get_current_object\n",
            "    raise RuntimeError(unbound_message) from None\n",
            "RuntimeError: Working outside of request context.\n",
            "\n",
            "This typically means that you attempted to use functionality that needed\n",
            "an active HTTP request. Consult the documentation on testing for\n",
            "information about how to avoid this problem.\n"
          ]
        },
        {
          "output_type": "stream",
          "name": "stdout",
          "text": [
            "\u001b[2K   \u001b[90m━━━━━━━━━━━━━━━━━━━━━━━━━━━━━━━━━━━━━━━━\u001b[0m \u001b[32m475.3/475.3 MB\u001b[0m \u001b[31m3.5 MB/s\u001b[0m eta \u001b[36m0:00:00\u001b[0m\n",
            "\u001b[?25hDownloading keras-2.15.0-py3-none-any.whl (1.7 MB)\n",
            "\u001b[2K   \u001b[90m━━━━━━━━━━━━━━━━━━━━━━━━━━━━━━━━━━━━━━━━\u001b[0m \u001b[32m1.7/1.7 MB\u001b[0m \u001b[31m46.9 MB/s\u001b[0m eta \u001b[36m0:00:00\u001b[0m\n",
            "\u001b[?25hDownloading ml_dtypes-0.3.2-cp311-cp311-manylinux_2_17_x86_64.manylinux2014_x86_64.whl (2.2 MB)\n",
            "\u001b[2K   \u001b[90m━━━━━━━━━━━━━━━━━━━━━━━━━━━━━━━━━━━━━━━━\u001b[0m \u001b[32m2.2/2.2 MB\u001b[0m \u001b[31m56.3 MB/s\u001b[0m eta \u001b[36m0:00:00\u001b[0m\n",
            "\u001b[?25hDownloading tensorboard-2.15.2-py3-none-any.whl (5.5 MB)\n",
            "\u001b[2K   \u001b[90m━━━━━━━━━━━━━━━━━━━━━━━━━━━━━━━━━━━━━━━━\u001b[0m \u001b[32m5.5/5.5 MB\u001b[0m \u001b[31m71.6 MB/s\u001b[0m eta \u001b[36m0:00:00\u001b[0m\n",
            "\u001b[?25hDownloading tensorflow_estimator-2.15.0-py2.py3-none-any.whl (441 kB)\n",
            "\u001b[2K   \u001b[90m━━━━━━━━━━━━━━━━━━━━━━━━━━━━━━━━━━━━━━━━\u001b[0m \u001b[32m442.0/442.0 kB\u001b[0m \u001b[31m24.9 MB/s\u001b[0m eta \u001b[36m0:00:00\u001b[0m\n",
            "\u001b[?25hDownloading wrapt-1.14.1-cp311-cp311-manylinux_2_5_x86_64.manylinux1_x86_64.manylinux_2_17_x86_64.manylinux2014_x86_64.whl (78 kB)\n",
            "\u001b[2K   \u001b[90m━━━━━━━━━━━━━━━━━━━━━━━━━━━━━━━━━━━━━━━━\u001b[0m \u001b[32m78.4/78.4 kB\u001b[0m \u001b[31m6.7 MB/s\u001b[0m eta \u001b[36m0:00:00\u001b[0m\n",
            "\u001b[?25h"
          ]
        },
        {
          "output_type": "stream",
          "name": "stderr",
          "text": [
            "ERROR:root:Unexpected exception finding object shape\n",
            "Traceback (most recent call last):\n",
            "  File \"/usr/local/lib/python3.11/dist-packages/google/colab/_debugpy_repr.py\", line 54, in get_shape\n",
            "    shape = getattr(obj, 'shape', None)\n",
            "            ^^^^^^^^^^^^^^^^^^^^^^^^^^^\n",
            "  File \"/usr/local/lib/python3.11/dist-packages/werkzeug/local.py\", line 318, in __get__\n",
            "    obj = instance._get_current_object()\n",
            "          ^^^^^^^^^^^^^^^^^^^^^^^^^^^^^^\n",
            "  File \"/usr/local/lib/python3.11/dist-packages/werkzeug/local.py\", line 519, in _get_current_object\n",
            "    raise RuntimeError(unbound_message) from None\n",
            "RuntimeError: Working outside of request context.\n",
            "\n",
            "This typically means that you attempted to use functionality that needed\n",
            "an active HTTP request. Consult the documentation on testing for\n",
            "information about how to avoid this problem.\n",
            "ERROR:root:Unexpected exception finding object shape\n",
            "Traceback (most recent call last):\n",
            "  File \"/usr/local/lib/python3.11/dist-packages/google/colab/_debugpy_repr.py\", line 54, in get_shape\n",
            "    shape = getattr(obj, 'shape', None)\n",
            "            ^^^^^^^^^^^^^^^^^^^^^^^^^^^\n",
            "  File \"/usr/local/lib/python3.11/dist-packages/werkzeug/local.py\", line 318, in __get__\n",
            "    obj = instance._get_current_object()\n",
            "          ^^^^^^^^^^^^^^^^^^^^^^^^^^^^^^\n",
            "  File \"/usr/local/lib/python3.11/dist-packages/werkzeug/local.py\", line 519, in _get_current_object\n",
            "    raise RuntimeError(unbound_message) from None\n",
            "RuntimeError: Working outside of request context.\n",
            "\n",
            "This typically means that you attempted to use functionality that needed\n",
            "an active HTTP request. Consult the documentation on testing for\n",
            "information about how to avoid this problem.\n",
            "ERROR:root:Unexpected exception finding object shape\n",
            "Traceback (most recent call last):\n",
            "  File \"/usr/local/lib/python3.11/dist-packages/google/colab/_debugpy_repr.py\", line 54, in get_shape\n",
            "    shape = getattr(obj, 'shape', None)\n",
            "            ^^^^^^^^^^^^^^^^^^^^^^^^^^^\n",
            "  File \"/usr/local/lib/python3.11/dist-packages/werkzeug/local.py\", line 318, in __get__\n",
            "    obj = instance._get_current_object()\n",
            "          ^^^^^^^^^^^^^^^^^^^^^^^^^^^^^^\n",
            "  File \"/usr/local/lib/python3.11/dist-packages/werkzeug/local.py\", line 519, in _get_current_object\n",
            "    raise RuntimeError(unbound_message) from None\n",
            "RuntimeError: Working outside of request context.\n",
            "\n",
            "This typically means that you attempted to use functionality that needed\n",
            "an active HTTP request. Consult the documentation on testing for\n",
            "information about how to avoid this problem.\n",
            "ERROR:root:Unexpected exception finding object shape\n",
            "Traceback (most recent call last):\n",
            "  File \"/usr/local/lib/python3.11/dist-packages/google/colab/_debugpy_repr.py\", line 54, in get_shape\n",
            "    shape = getattr(obj, 'shape', None)\n",
            "            ^^^^^^^^^^^^^^^^^^^^^^^^^^^\n",
            "  File \"/usr/local/lib/python3.11/dist-packages/werkzeug/local.py\", line 318, in __get__\n",
            "    obj = instance._get_current_object()\n",
            "          ^^^^^^^^^^^^^^^^^^^^^^^^^^^^^^\n",
            "  File \"/usr/local/lib/python3.11/dist-packages/werkzeug/local.py\", line 519, in _get_current_object\n",
            "    raise RuntimeError(unbound_message) from None\n",
            "RuntimeError: Working outside of request context.\n",
            "\n",
            "This typically means that you attempted to use functionality that needed\n",
            "an active HTTP request. Consult the documentation on testing for\n",
            "information about how to avoid this problem.\n"
          ]
        },
        {
          "output_type": "stream",
          "name": "stdout",
          "text": [
            "Installing collected packages: wrapt, tensorflow-estimator, ml-dtypes, keras, tensorboard, tensorflow\n",
            "  Attempting uninstall: wrapt\n",
            "    Found existing installation: wrapt 1.17.2\n",
            "    Uninstalling wrapt-1.17.2:\n",
            "      Successfully uninstalled wrapt-1.17.2\n",
            "  Attempting uninstall: ml-dtypes\n",
            "    Found existing installation: ml-dtypes 0.4.1\n",
            "    Uninstalling ml-dtypes-0.4.1:\n",
            "      Successfully uninstalled ml-dtypes-0.4.1\n",
            "  Attempting uninstall: keras\n"
          ]
        },
        {
          "output_type": "stream",
          "name": "stderr",
          "text": [
            "ERROR:root:Unexpected exception finding object shape\n",
            "Traceback (most recent call last):\n",
            "  File \"/usr/local/lib/python3.11/dist-packages/google/colab/_debugpy_repr.py\", line 54, in get_shape\n",
            "    shape = getattr(obj, 'shape', None)\n",
            "            ^^^^^^^^^^^^^^^^^^^^^^^^^^^\n",
            "  File \"/usr/local/lib/python3.11/dist-packages/werkzeug/local.py\", line 318, in __get__\n",
            "    obj = instance._get_current_object()\n",
            "          ^^^^^^^^^^^^^^^^^^^^^^^^^^^^^^\n",
            "  File \"/usr/local/lib/python3.11/dist-packages/werkzeug/local.py\", line 519, in _get_current_object\n",
            "    raise RuntimeError(unbound_message) from None\n",
            "RuntimeError: Working outside of request context.\n",
            "\n",
            "This typically means that you attempted to use functionality that needed\n",
            "an active HTTP request. Consult the documentation on testing for\n",
            "information about how to avoid this problem.\n"
          ]
        },
        {
          "output_type": "stream",
          "name": "stdout",
          "text": [
            "    Found existing installation: keras 3.8.0\n",
            "    Uninstalling keras-3.8.0:\n"
          ]
        },
        {
          "output_type": "stream",
          "name": "stderr",
          "text": [
            "ERROR:root:Unexpected exception finding object shape\n",
            "Traceback (most recent call last):\n",
            "  File \"/usr/local/lib/python3.11/dist-packages/google/colab/_debugpy_repr.py\", line 54, in get_shape\n",
            "    shape = getattr(obj, 'shape', None)\n",
            "            ^^^^^^^^^^^^^^^^^^^^^^^^^^^\n",
            "  File \"/usr/local/lib/python3.11/dist-packages/werkzeug/local.py\", line 318, in __get__\n",
            "    obj = instance._get_current_object()\n",
            "          ^^^^^^^^^^^^^^^^^^^^^^^^^^^^^^\n",
            "  File \"/usr/local/lib/python3.11/dist-packages/werkzeug/local.py\", line 519, in _get_current_object\n",
            "    raise RuntimeError(unbound_message) from None\n",
            "RuntimeError: Working outside of request context.\n",
            "\n",
            "This typically means that you attempted to use functionality that needed\n",
            "an active HTTP request. Consult the documentation on testing for\n",
            "information about how to avoid this problem.\n"
          ]
        },
        {
          "output_type": "stream",
          "name": "stdout",
          "text": [
            "      Successfully uninstalled keras-3.8.0\n"
          ]
        },
        {
          "output_type": "stream",
          "name": "stderr",
          "text": [
            "ERROR:root:Unexpected exception finding object shape\n",
            "Traceback (most recent call last):\n",
            "  File \"/usr/local/lib/python3.11/dist-packages/google/colab/_debugpy_repr.py\", line 54, in get_shape\n",
            "    shape = getattr(obj, 'shape', None)\n",
            "            ^^^^^^^^^^^^^^^^^^^^^^^^^^^\n",
            "  File \"/usr/local/lib/python3.11/dist-packages/werkzeug/local.py\", line 318, in __get__\n",
            "    obj = instance._get_current_object()\n",
            "          ^^^^^^^^^^^^^^^^^^^^^^^^^^^^^^\n",
            "  File \"/usr/local/lib/python3.11/dist-packages/werkzeug/local.py\", line 519, in _get_current_object\n",
            "    raise RuntimeError(unbound_message) from None\n",
            "RuntimeError: Working outside of request context.\n",
            "\n",
            "This typically means that you attempted to use functionality that needed\n",
            "an active HTTP request. Consult the documentation on testing for\n",
            "information about how to avoid this problem.\n"
          ]
        },
        {
          "output_type": "stream",
          "name": "stdout",
          "text": [
            "  Attempting uninstall: tensorboard\n",
            "    Found existing installation: tensorboard 2.18.0\n",
            "    Uninstalling tensorboard-2.18.0:\n",
            "      Successfully uninstalled tensorboard-2.18.0\n"
          ]
        },
        {
          "output_type": "stream",
          "name": "stderr",
          "text": [
            "ERROR:root:Unexpected exception finding object shape\n",
            "Traceback (most recent call last):\n",
            "  File \"/usr/local/lib/python3.11/dist-packages/google/colab/_debugpy_repr.py\", line 54, in get_shape\n",
            "    shape = getattr(obj, 'shape', None)\n",
            "            ^^^^^^^^^^^^^^^^^^^^^^^^^^^\n",
            "  File \"/usr/local/lib/python3.11/dist-packages/werkzeug/local.py\", line 318, in __get__\n",
            "    obj = instance._get_current_object()\n",
            "          ^^^^^^^^^^^^^^^^^^^^^^^^^^^^^^\n",
            "  File \"/usr/local/lib/python3.11/dist-packages/werkzeug/local.py\", line 519, in _get_current_object\n",
            "    raise RuntimeError(unbound_message) from None\n",
            "RuntimeError: Working outside of request context.\n",
            "\n",
            "This typically means that you attempted to use functionality that needed\n",
            "an active HTTP request. Consult the documentation on testing for\n",
            "information about how to avoid this problem.\n"
          ]
        },
        {
          "output_type": "stream",
          "name": "stdout",
          "text": [
            "  Attempting uninstall: tensorflow\n",
            "    Found existing installation: tensorflow 2.18.0\n"
          ]
        },
        {
          "output_type": "stream",
          "name": "stderr",
          "text": [
            "ERROR:root:Unexpected exception finding object shape\n",
            "Traceback (most recent call last):\n",
            "  File \"/usr/local/lib/python3.11/dist-packages/google/colab/_debugpy_repr.py\", line 54, in get_shape\n",
            "    shape = getattr(obj, 'shape', None)\n",
            "            ^^^^^^^^^^^^^^^^^^^^^^^^^^^\n",
            "  File \"/usr/local/lib/python3.11/dist-packages/werkzeug/local.py\", line 318, in __get__\n",
            "    obj = instance._get_current_object()\n",
            "          ^^^^^^^^^^^^^^^^^^^^^^^^^^^^^^\n",
            "  File \"/usr/local/lib/python3.11/dist-packages/werkzeug/local.py\", line 519, in _get_current_object\n",
            "    raise RuntimeError(unbound_message) from None\n",
            "RuntimeError: Working outside of request context.\n",
            "\n",
            "This typically means that you attempted to use functionality that needed\n",
            "an active HTTP request. Consult the documentation on testing for\n",
            "information about how to avoid this problem.\n",
            "ERROR:root:Unexpected exception finding object shape\n",
            "Traceback (most recent call last):\n",
            "  File \"/usr/local/lib/python3.11/dist-packages/google/colab/_debugpy_repr.py\", line 54, in get_shape\n",
            "    shape = getattr(obj, 'shape', None)\n",
            "            ^^^^^^^^^^^^^^^^^^^^^^^^^^^\n",
            "  File \"/usr/local/lib/python3.11/dist-packages/werkzeug/local.py\", line 318, in __get__\n",
            "    obj = instance._get_current_object()\n",
            "          ^^^^^^^^^^^^^^^^^^^^^^^^^^^^^^\n",
            "  File \"/usr/local/lib/python3.11/dist-packages/werkzeug/local.py\", line 519, in _get_current_object\n",
            "    raise RuntimeError(unbound_message) from None\n",
            "RuntimeError: Working outside of request context.\n",
            "\n",
            "This typically means that you attempted to use functionality that needed\n",
            "an active HTTP request. Consult the documentation on testing for\n",
            "information about how to avoid this problem.\n"
          ]
        },
        {
          "output_type": "stream",
          "name": "stdout",
          "text": [
            "    Uninstalling tensorflow-2.18.0:\n"
          ]
        },
        {
          "output_type": "stream",
          "name": "stderr",
          "text": [
            "ERROR:root:Unexpected exception finding object shape\n",
            "Traceback (most recent call last):\n",
            "  File \"/usr/local/lib/python3.11/dist-packages/google/colab/_debugpy_repr.py\", line 54, in get_shape\n",
            "    shape = getattr(obj, 'shape', None)\n",
            "            ^^^^^^^^^^^^^^^^^^^^^^^^^^^\n",
            "  File \"/usr/local/lib/python3.11/dist-packages/werkzeug/local.py\", line 318, in __get__\n",
            "    obj = instance._get_current_object()\n",
            "          ^^^^^^^^^^^^^^^^^^^^^^^^^^^^^^\n",
            "  File \"/usr/local/lib/python3.11/dist-packages/werkzeug/local.py\", line 519, in _get_current_object\n",
            "    raise RuntimeError(unbound_message) from None\n",
            "RuntimeError: Working outside of request context.\n",
            "\n",
            "This typically means that you attempted to use functionality that needed\n",
            "an active HTTP request. Consult the documentation on testing for\n",
            "information about how to avoid this problem.\n",
            "ERROR:root:Unexpected exception finding object shape\n",
            "Traceback (most recent call last):\n",
            "  File \"/usr/local/lib/python3.11/dist-packages/google/colab/_debugpy_repr.py\", line 54, in get_shape\n",
            "    shape = getattr(obj, 'shape', None)\n",
            "            ^^^^^^^^^^^^^^^^^^^^^^^^^^^\n",
            "  File \"/usr/local/lib/python3.11/dist-packages/werkzeug/local.py\", line 318, in __get__\n",
            "    obj = instance._get_current_object()\n",
            "          ^^^^^^^^^^^^^^^^^^^^^^^^^^^^^^\n",
            "  File \"/usr/local/lib/python3.11/dist-packages/werkzeug/local.py\", line 519, in _get_current_object\n",
            "    raise RuntimeError(unbound_message) from None\n",
            "RuntimeError: Working outside of request context.\n",
            "\n",
            "This typically means that you attempted to use functionality that needed\n",
            "an active HTTP request. Consult the documentation on testing for\n",
            "information about how to avoid this problem.\n",
            "ERROR:root:Unexpected exception finding object shape\n",
            "Traceback (most recent call last):\n",
            "  File \"/usr/local/lib/python3.11/dist-packages/google/colab/_debugpy_repr.py\", line 54, in get_shape\n",
            "    shape = getattr(obj, 'shape', None)\n",
            "            ^^^^^^^^^^^^^^^^^^^^^^^^^^^\n",
            "  File \"/usr/local/lib/python3.11/dist-packages/werkzeug/local.py\", line 318, in __get__\n",
            "    obj = instance._get_current_object()\n",
            "          ^^^^^^^^^^^^^^^^^^^^^^^^^^^^^^\n",
            "  File \"/usr/local/lib/python3.11/dist-packages/werkzeug/local.py\", line 519, in _get_current_object\n",
            "    raise RuntimeError(unbound_message) from None\n",
            "RuntimeError: Working outside of request context.\n",
            "\n",
            "This typically means that you attempted to use functionality that needed\n",
            "an active HTTP request. Consult the documentation on testing for\n",
            "information about how to avoid this problem.\n",
            "ERROR:root:Unexpected exception finding object shape\n",
            "Traceback (most recent call last):\n",
            "  File \"/usr/local/lib/python3.11/dist-packages/google/colab/_debugpy_repr.py\", line 54, in get_shape\n",
            "    shape = getattr(obj, 'shape', None)\n",
            "            ^^^^^^^^^^^^^^^^^^^^^^^^^^^\n",
            "  File \"/usr/local/lib/python3.11/dist-packages/werkzeug/local.py\", line 318, in __get__\n",
            "    obj = instance._get_current_object()\n",
            "          ^^^^^^^^^^^^^^^^^^^^^^^^^^^^^^\n",
            "  File \"/usr/local/lib/python3.11/dist-packages/werkzeug/local.py\", line 519, in _get_current_object\n",
            "    raise RuntimeError(unbound_message) from None\n",
            "RuntimeError: Working outside of request context.\n",
            "\n",
            "This typically means that you attempted to use functionality that needed\n",
            "an active HTTP request. Consult the documentation on testing for\n",
            "information about how to avoid this problem.\n",
            "ERROR:root:Unexpected exception finding object shape\n",
            "Traceback (most recent call last):\n",
            "  File \"/usr/local/lib/python3.11/dist-packages/google/colab/_debugpy_repr.py\", line 54, in get_shape\n",
            "    shape = getattr(obj, 'shape', None)\n",
            "            ^^^^^^^^^^^^^^^^^^^^^^^^^^^\n",
            "  File \"/usr/local/lib/python3.11/dist-packages/werkzeug/local.py\", line 318, in __get__\n",
            "    obj = instance._get_current_object()\n",
            "          ^^^^^^^^^^^^^^^^^^^^^^^^^^^^^^\n",
            "  File \"/usr/local/lib/python3.11/dist-packages/werkzeug/local.py\", line 519, in _get_current_object\n",
            "    raise RuntimeError(unbound_message) from None\n",
            "RuntimeError: Working outside of request context.\n",
            "\n",
            "This typically means that you attempted to use functionality that needed\n",
            "an active HTTP request. Consult the documentation on testing for\n",
            "information about how to avoid this problem.\n",
            "ERROR:root:Unexpected exception finding object shape\n",
            "Traceback (most recent call last):\n",
            "  File \"/usr/local/lib/python3.11/dist-packages/google/colab/_debugpy_repr.py\", line 54, in get_shape\n",
            "    shape = getattr(obj, 'shape', None)\n",
            "            ^^^^^^^^^^^^^^^^^^^^^^^^^^^\n",
            "  File \"/usr/local/lib/python3.11/dist-packages/werkzeug/local.py\", line 318, in __get__\n",
            "    obj = instance._get_current_object()\n",
            "          ^^^^^^^^^^^^^^^^^^^^^^^^^^^^^^\n",
            "  File \"/usr/local/lib/python3.11/dist-packages/werkzeug/local.py\", line 519, in _get_current_object\n",
            "    raise RuntimeError(unbound_message) from None\n",
            "RuntimeError: Working outside of request context.\n",
            "\n",
            "This typically means that you attempted to use functionality that needed\n",
            "an active HTTP request. Consult the documentation on testing for\n",
            "information about how to avoid this problem.\n",
            "ERROR:root:Unexpected exception finding object shape\n",
            "Traceback (most recent call last):\n",
            "  File \"/usr/local/lib/python3.11/dist-packages/google/colab/_debugpy_repr.py\", line 54, in get_shape\n",
            "    shape = getattr(obj, 'shape', None)\n",
            "            ^^^^^^^^^^^^^^^^^^^^^^^^^^^\n",
            "  File \"/usr/local/lib/python3.11/dist-packages/werkzeug/local.py\", line 318, in __get__\n",
            "    obj = instance._get_current_object()\n",
            "          ^^^^^^^^^^^^^^^^^^^^^^^^^^^^^^\n",
            "  File \"/usr/local/lib/python3.11/dist-packages/werkzeug/local.py\", line 519, in _get_current_object\n",
            "    raise RuntimeError(unbound_message) from None\n",
            "RuntimeError: Working outside of request context.\n",
            "\n",
            "This typically means that you attempted to use functionality that needed\n",
            "an active HTTP request. Consult the documentation on testing for\n",
            "information about how to avoid this problem.\n",
            "ERROR:root:Unexpected exception finding object shape\n",
            "Traceback (most recent call last):\n",
            "  File \"/usr/local/lib/python3.11/dist-packages/google/colab/_debugpy_repr.py\", line 54, in get_shape\n",
            "    shape = getattr(obj, 'shape', None)\n",
            "            ^^^^^^^^^^^^^^^^^^^^^^^^^^^\n",
            "  File \"/usr/local/lib/python3.11/dist-packages/werkzeug/local.py\", line 318, in __get__\n",
            "    obj = instance._get_current_object()\n",
            "          ^^^^^^^^^^^^^^^^^^^^^^^^^^^^^^\n",
            "  File \"/usr/local/lib/python3.11/dist-packages/werkzeug/local.py\", line 519, in _get_current_object\n",
            "    raise RuntimeError(unbound_message) from None\n",
            "RuntimeError: Working outside of request context.\n",
            "\n",
            "This typically means that you attempted to use functionality that needed\n",
            "an active HTTP request. Consult the documentation on testing for\n",
            "information about how to avoid this problem.\n",
            "ERROR:root:Unexpected exception finding object shape\n",
            "Traceback (most recent call last):\n",
            "  File \"/usr/local/lib/python3.11/dist-packages/google/colab/_debugpy_repr.py\", line 54, in get_shape\n",
            "    shape = getattr(obj, 'shape', None)\n",
            "            ^^^^^^^^^^^^^^^^^^^^^^^^^^^\n",
            "  File \"/usr/local/lib/python3.11/dist-packages/werkzeug/local.py\", line 318, in __get__\n",
            "    obj = instance._get_current_object()\n",
            "          ^^^^^^^^^^^^^^^^^^^^^^^^^^^^^^\n",
            "  File \"/usr/local/lib/python3.11/dist-packages/werkzeug/local.py\", line 519, in _get_current_object\n",
            "    raise RuntimeError(unbound_message) from None\n",
            "RuntimeError: Working outside of request context.\n",
            "\n",
            "This typically means that you attempted to use functionality that needed\n",
            "an active HTTP request. Consult the documentation on testing for\n",
            "information about how to avoid this problem.\n",
            "ERROR:root:Unexpected exception finding object shape\n",
            "Traceback (most recent call last):\n",
            "  File \"/usr/local/lib/python3.11/dist-packages/google/colab/_debugpy_repr.py\", line 54, in get_shape\n",
            "    shape = getattr(obj, 'shape', None)\n",
            "            ^^^^^^^^^^^^^^^^^^^^^^^^^^^\n",
            "  File \"/usr/local/lib/python3.11/dist-packages/werkzeug/local.py\", line 318, in __get__\n",
            "    obj = instance._get_current_object()\n",
            "          ^^^^^^^^^^^^^^^^^^^^^^^^^^^^^^\n",
            "  File \"/usr/local/lib/python3.11/dist-packages/werkzeug/local.py\", line 519, in _get_current_object\n",
            "    raise RuntimeError(unbound_message) from None\n",
            "RuntimeError: Working outside of request context.\n",
            "\n",
            "This typically means that you attempted to use functionality that needed\n",
            "an active HTTP request. Consult the documentation on testing for\n",
            "information about how to avoid this problem.\n",
            "ERROR:root:Unexpected exception finding object shape\n",
            "Traceback (most recent call last):\n",
            "  File \"/usr/local/lib/python3.11/dist-packages/google/colab/_debugpy_repr.py\", line 54, in get_shape\n",
            "    shape = getattr(obj, 'shape', None)\n",
            "            ^^^^^^^^^^^^^^^^^^^^^^^^^^^\n",
            "  File \"/usr/local/lib/python3.11/dist-packages/werkzeug/local.py\", line 318, in __get__\n",
            "    obj = instance._get_current_object()\n",
            "          ^^^^^^^^^^^^^^^^^^^^^^^^^^^^^^\n",
            "  File \"/usr/local/lib/python3.11/dist-packages/werkzeug/local.py\", line 519, in _get_current_object\n",
            "    raise RuntimeError(unbound_message) from None\n",
            "RuntimeError: Working outside of request context.\n",
            "\n",
            "This typically means that you attempted to use functionality that needed\n",
            "an active HTTP request. Consult the documentation on testing for\n",
            "information about how to avoid this problem.\n",
            "ERROR:root:Unexpected exception finding object shape\n",
            "Traceback (most recent call last):\n",
            "  File \"/usr/local/lib/python3.11/dist-packages/google/colab/_debugpy_repr.py\", line 54, in get_shape\n",
            "    shape = getattr(obj, 'shape', None)\n",
            "            ^^^^^^^^^^^^^^^^^^^^^^^^^^^\n",
            "  File \"/usr/local/lib/python3.11/dist-packages/werkzeug/local.py\", line 318, in __get__\n",
            "    obj = instance._get_current_object()\n",
            "          ^^^^^^^^^^^^^^^^^^^^^^^^^^^^^^\n",
            "  File \"/usr/local/lib/python3.11/dist-packages/werkzeug/local.py\", line 519, in _get_current_object\n",
            "    raise RuntimeError(unbound_message) from None\n",
            "RuntimeError: Working outside of request context.\n",
            "\n",
            "This typically means that you attempted to use functionality that needed\n",
            "an active HTTP request. Consult the documentation on testing for\n",
            "information about how to avoid this problem.\n",
            "ERROR:root:Unexpected exception finding object shape\n",
            "Traceback (most recent call last):\n",
            "  File \"/usr/local/lib/python3.11/dist-packages/google/colab/_debugpy_repr.py\", line 54, in get_shape\n",
            "    shape = getattr(obj, 'shape', None)\n",
            "            ^^^^^^^^^^^^^^^^^^^^^^^^^^^\n",
            "  File \"/usr/local/lib/python3.11/dist-packages/werkzeug/local.py\", line 318, in __get__\n",
            "    obj = instance._get_current_object()\n",
            "          ^^^^^^^^^^^^^^^^^^^^^^^^^^^^^^\n",
            "  File \"/usr/local/lib/python3.11/dist-packages/werkzeug/local.py\", line 519, in _get_current_object\n",
            "    raise RuntimeError(unbound_message) from None\n",
            "RuntimeError: Working outside of request context.\n",
            "\n",
            "This typically means that you attempted to use functionality that needed\n",
            "an active HTTP request. Consult the documentation on testing for\n",
            "information about how to avoid this problem.\n",
            "ERROR:root:Unexpected exception finding object shape\n",
            "Traceback (most recent call last):\n",
            "  File \"/usr/local/lib/python3.11/dist-packages/google/colab/_debugpy_repr.py\", line 54, in get_shape\n",
            "    shape = getattr(obj, 'shape', None)\n",
            "            ^^^^^^^^^^^^^^^^^^^^^^^^^^^\n",
            "  File \"/usr/local/lib/python3.11/dist-packages/werkzeug/local.py\", line 318, in __get__\n",
            "    obj = instance._get_current_object()\n",
            "          ^^^^^^^^^^^^^^^^^^^^^^^^^^^^^^\n",
            "  File \"/usr/local/lib/python3.11/dist-packages/werkzeug/local.py\", line 519, in _get_current_object\n",
            "    raise RuntimeError(unbound_message) from None\n",
            "RuntimeError: Working outside of request context.\n",
            "\n",
            "This typically means that you attempted to use functionality that needed\n",
            "an active HTTP request. Consult the documentation on testing for\n",
            "information about how to avoid this problem.\n",
            "ERROR:root:Unexpected exception finding object shape\n",
            "Traceback (most recent call last):\n",
            "  File \"/usr/local/lib/python3.11/dist-packages/google/colab/_debugpy_repr.py\", line 54, in get_shape\n",
            "    shape = getattr(obj, 'shape', None)\n",
            "            ^^^^^^^^^^^^^^^^^^^^^^^^^^^\n",
            "  File \"/usr/local/lib/python3.11/dist-packages/werkzeug/local.py\", line 318, in __get__\n",
            "    obj = instance._get_current_object()\n",
            "          ^^^^^^^^^^^^^^^^^^^^^^^^^^^^^^\n",
            "  File \"/usr/local/lib/python3.11/dist-packages/werkzeug/local.py\", line 519, in _get_current_object\n",
            "    raise RuntimeError(unbound_message) from None\n",
            "RuntimeError: Working outside of request context.\n",
            "\n",
            "This typically means that you attempted to use functionality that needed\n",
            "an active HTTP request. Consult the documentation on testing for\n",
            "information about how to avoid this problem.\n",
            "ERROR:root:Unexpected exception finding object shape\n",
            "Traceback (most recent call last):\n",
            "  File \"/usr/local/lib/python3.11/dist-packages/google/colab/_debugpy_repr.py\", line 54, in get_shape\n",
            "    shape = getattr(obj, 'shape', None)\n",
            "            ^^^^^^^^^^^^^^^^^^^^^^^^^^^\n",
            "  File \"/usr/local/lib/python3.11/dist-packages/werkzeug/local.py\", line 318, in __get__\n",
            "    obj = instance._get_current_object()\n",
            "          ^^^^^^^^^^^^^^^^^^^^^^^^^^^^^^\n",
            "  File \"/usr/local/lib/python3.11/dist-packages/werkzeug/local.py\", line 519, in _get_current_object\n",
            "    raise RuntimeError(unbound_message) from None\n",
            "RuntimeError: Working outside of request context.\n",
            "\n",
            "This typically means that you attempted to use functionality that needed\n",
            "an active HTTP request. Consult the documentation on testing for\n",
            "information about how to avoid this problem.\n",
            "ERROR:root:Unexpected exception finding object shape\n",
            "Traceback (most recent call last):\n",
            "  File \"/usr/local/lib/python3.11/dist-packages/google/colab/_debugpy_repr.py\", line 54, in get_shape\n",
            "    shape = getattr(obj, 'shape', None)\n",
            "            ^^^^^^^^^^^^^^^^^^^^^^^^^^^\n",
            "  File \"/usr/local/lib/python3.11/dist-packages/werkzeug/local.py\", line 318, in __get__\n",
            "    obj = instance._get_current_object()\n",
            "          ^^^^^^^^^^^^^^^^^^^^^^^^^^^^^^\n",
            "  File \"/usr/local/lib/python3.11/dist-packages/werkzeug/local.py\", line 519, in _get_current_object\n",
            "    raise RuntimeError(unbound_message) from None\n",
            "RuntimeError: Working outside of request context.\n",
            "\n",
            "This typically means that you attempted to use functionality that needed\n",
            "an active HTTP request. Consult the documentation on testing for\n",
            "information about how to avoid this problem.\n",
            "ERROR:root:Unexpected exception finding object shape\n",
            "Traceback (most recent call last):\n",
            "  File \"/usr/local/lib/python3.11/dist-packages/google/colab/_debugpy_repr.py\", line 54, in get_shape\n",
            "    shape = getattr(obj, 'shape', None)\n",
            "            ^^^^^^^^^^^^^^^^^^^^^^^^^^^\n",
            "  File \"/usr/local/lib/python3.11/dist-packages/werkzeug/local.py\", line 318, in __get__\n",
            "    obj = instance._get_current_object()\n",
            "          ^^^^^^^^^^^^^^^^^^^^^^^^^^^^^^\n",
            "  File \"/usr/local/lib/python3.11/dist-packages/werkzeug/local.py\", line 519, in _get_current_object\n",
            "    raise RuntimeError(unbound_message) from None\n",
            "RuntimeError: Working outside of request context.\n",
            "\n",
            "This typically means that you attempted to use functionality that needed\n",
            "an active HTTP request. Consult the documentation on testing for\n",
            "information about how to avoid this problem.\n",
            "ERROR:root:Unexpected exception finding object shape\n",
            "Traceback (most recent call last):\n",
            "  File \"/usr/local/lib/python3.11/dist-packages/google/colab/_debugpy_repr.py\", line 54, in get_shape\n",
            "    shape = getattr(obj, 'shape', None)\n",
            "            ^^^^^^^^^^^^^^^^^^^^^^^^^^^\n",
            "  File \"/usr/local/lib/python3.11/dist-packages/werkzeug/local.py\", line 318, in __get__\n",
            "    obj = instance._get_current_object()\n",
            "          ^^^^^^^^^^^^^^^^^^^^^^^^^^^^^^\n",
            "  File \"/usr/local/lib/python3.11/dist-packages/werkzeug/local.py\", line 519, in _get_current_object\n",
            "    raise RuntimeError(unbound_message) from None\n",
            "RuntimeError: Working outside of request context.\n",
            "\n",
            "This typically means that you attempted to use functionality that needed\n",
            "an active HTTP request. Consult the documentation on testing for\n",
            "information about how to avoid this problem.\n",
            "ERROR:root:Unexpected exception finding object shape\n",
            "Traceback (most recent call last):\n",
            "  File \"/usr/local/lib/python3.11/dist-packages/google/colab/_debugpy_repr.py\", line 54, in get_shape\n",
            "    shape = getattr(obj, 'shape', None)\n",
            "            ^^^^^^^^^^^^^^^^^^^^^^^^^^^\n",
            "  File \"/usr/local/lib/python3.11/dist-packages/werkzeug/local.py\", line 318, in __get__\n",
            "    obj = instance._get_current_object()\n",
            "          ^^^^^^^^^^^^^^^^^^^^^^^^^^^^^^\n",
            "  File \"/usr/local/lib/python3.11/dist-packages/werkzeug/local.py\", line 519, in _get_current_object\n",
            "    raise RuntimeError(unbound_message) from None\n",
            "RuntimeError: Working outside of request context.\n",
            "\n",
            "This typically means that you attempted to use functionality that needed\n",
            "an active HTTP request. Consult the documentation on testing for\n",
            "information about how to avoid this problem.\n",
            "ERROR:root:Unexpected exception finding object shape\n",
            "Traceback (most recent call last):\n",
            "  File \"/usr/local/lib/python3.11/dist-packages/google/colab/_debugpy_repr.py\", line 54, in get_shape\n",
            "    shape = getattr(obj, 'shape', None)\n",
            "            ^^^^^^^^^^^^^^^^^^^^^^^^^^^\n",
            "  File \"/usr/local/lib/python3.11/dist-packages/werkzeug/local.py\", line 318, in __get__\n",
            "    obj = instance._get_current_object()\n",
            "          ^^^^^^^^^^^^^^^^^^^^^^^^^^^^^^\n",
            "  File \"/usr/local/lib/python3.11/dist-packages/werkzeug/local.py\", line 519, in _get_current_object\n",
            "    raise RuntimeError(unbound_message) from None\n",
            "RuntimeError: Working outside of request context.\n",
            "\n",
            "This typically means that you attempted to use functionality that needed\n",
            "an active HTTP request. Consult the documentation on testing for\n",
            "information about how to avoid this problem.\n",
            "ERROR:root:Unexpected exception finding object shape\n",
            "Traceback (most recent call last):\n",
            "  File \"/usr/local/lib/python3.11/dist-packages/google/colab/_debugpy_repr.py\", line 54, in get_shape\n",
            "    shape = getattr(obj, 'shape', None)\n",
            "            ^^^^^^^^^^^^^^^^^^^^^^^^^^^\n",
            "  File \"/usr/local/lib/python3.11/dist-packages/werkzeug/local.py\", line 318, in __get__\n",
            "    obj = instance._get_current_object()\n",
            "          ^^^^^^^^^^^^^^^^^^^^^^^^^^^^^^\n",
            "  File \"/usr/local/lib/python3.11/dist-packages/werkzeug/local.py\", line 519, in _get_current_object\n",
            "    raise RuntimeError(unbound_message) from None\n",
            "RuntimeError: Working outside of request context.\n",
            "\n",
            "This typically means that you attempted to use functionality that needed\n",
            "an active HTTP request. Consult the documentation on testing for\n",
            "information about how to avoid this problem.\n",
            "ERROR:root:Unexpected exception finding object shape\n",
            "Traceback (most recent call last):\n",
            "  File \"/usr/local/lib/python3.11/dist-packages/google/colab/_debugpy_repr.py\", line 54, in get_shape\n",
            "    shape = getattr(obj, 'shape', None)\n",
            "            ^^^^^^^^^^^^^^^^^^^^^^^^^^^\n",
            "  File \"/usr/local/lib/python3.11/dist-packages/werkzeug/local.py\", line 318, in __get__\n",
            "    obj = instance._get_current_object()\n",
            "          ^^^^^^^^^^^^^^^^^^^^^^^^^^^^^^\n",
            "  File \"/usr/local/lib/python3.11/dist-packages/werkzeug/local.py\", line 519, in _get_current_object\n",
            "    raise RuntimeError(unbound_message) from None\n",
            "RuntimeError: Working outside of request context.\n",
            "\n",
            "This typically means that you attempted to use functionality that needed\n",
            "an active HTTP request. Consult the documentation on testing for\n",
            "information about how to avoid this problem.\n"
          ]
        },
        {
          "output_type": "stream",
          "name": "stdout",
          "text": [
            "      Successfully uninstalled tensorflow-2.18.0\n"
          ]
        },
        {
          "output_type": "stream",
          "name": "stderr",
          "text": [
            "ERROR:root:Unexpected exception finding object shape\n",
            "Traceback (most recent call last):\n",
            "  File \"/usr/local/lib/python3.11/dist-packages/google/colab/_debugpy_repr.py\", line 54, in get_shape\n",
            "    shape = getattr(obj, 'shape', None)\n",
            "            ^^^^^^^^^^^^^^^^^^^^^^^^^^^\n",
            "  File \"/usr/local/lib/python3.11/dist-packages/werkzeug/local.py\", line 318, in __get__\n",
            "    obj = instance._get_current_object()\n",
            "          ^^^^^^^^^^^^^^^^^^^^^^^^^^^^^^\n",
            "  File \"/usr/local/lib/python3.11/dist-packages/werkzeug/local.py\", line 519, in _get_current_object\n",
            "    raise RuntimeError(unbound_message) from None\n",
            "RuntimeError: Working outside of request context.\n",
            "\n",
            "This typically means that you attempted to use functionality that needed\n",
            "an active HTTP request. Consult the documentation on testing for\n",
            "information about how to avoid this problem.\n",
            "ERROR:root:Unexpected exception finding object shape\n",
            "Traceback (most recent call last):\n",
            "  File \"/usr/local/lib/python3.11/dist-packages/google/colab/_debugpy_repr.py\", line 54, in get_shape\n",
            "    shape = getattr(obj, 'shape', None)\n",
            "            ^^^^^^^^^^^^^^^^^^^^^^^^^^^\n",
            "  File \"/usr/local/lib/python3.11/dist-packages/werkzeug/local.py\", line 318, in __get__\n",
            "    obj = instance._get_current_object()\n",
            "          ^^^^^^^^^^^^^^^^^^^^^^^^^^^^^^\n",
            "  File \"/usr/local/lib/python3.11/dist-packages/werkzeug/local.py\", line 519, in _get_current_object\n",
            "    raise RuntimeError(unbound_message) from None\n",
            "RuntimeError: Working outside of request context.\n",
            "\n",
            "This typically means that you attempted to use functionality that needed\n",
            "an active HTTP request. Consult the documentation on testing for\n",
            "information about how to avoid this problem.\n",
            "ERROR:root:Unexpected exception finding object shape\n",
            "Traceback (most recent call last):\n",
            "  File \"/usr/local/lib/python3.11/dist-packages/google/colab/_debugpy_repr.py\", line 54, in get_shape\n",
            "    shape = getattr(obj, 'shape', None)\n",
            "            ^^^^^^^^^^^^^^^^^^^^^^^^^^^\n",
            "  File \"/usr/local/lib/python3.11/dist-packages/werkzeug/local.py\", line 318, in __get__\n",
            "    obj = instance._get_current_object()\n",
            "          ^^^^^^^^^^^^^^^^^^^^^^^^^^^^^^\n",
            "  File \"/usr/local/lib/python3.11/dist-packages/werkzeug/local.py\", line 519, in _get_current_object\n",
            "    raise RuntimeError(unbound_message) from None\n",
            "RuntimeError: Working outside of request context.\n",
            "\n",
            "This typically means that you attempted to use functionality that needed\n",
            "an active HTTP request. Consult the documentation on testing for\n",
            "information about how to avoid this problem.\n",
            "ERROR:root:Unexpected exception finding object shape\n",
            "Traceback (most recent call last):\n",
            "  File \"/usr/local/lib/python3.11/dist-packages/google/colab/_debugpy_repr.py\", line 54, in get_shape\n",
            "    shape = getattr(obj, 'shape', None)\n",
            "            ^^^^^^^^^^^^^^^^^^^^^^^^^^^\n",
            "  File \"/usr/local/lib/python3.11/dist-packages/werkzeug/local.py\", line 318, in __get__\n",
            "    obj = instance._get_current_object()\n",
            "          ^^^^^^^^^^^^^^^^^^^^^^^^^^^^^^\n",
            "  File \"/usr/local/lib/python3.11/dist-packages/werkzeug/local.py\", line 519, in _get_current_object\n",
            "    raise RuntimeError(unbound_message) from None\n",
            "RuntimeError: Working outside of request context.\n",
            "\n",
            "This typically means that you attempted to use functionality that needed\n",
            "an active HTTP request. Consult the documentation on testing for\n",
            "information about how to avoid this problem.\n",
            "ERROR:root:Unexpected exception finding object shape\n",
            "Traceback (most recent call last):\n",
            "  File \"/usr/local/lib/python3.11/dist-packages/google/colab/_debugpy_repr.py\", line 54, in get_shape\n",
            "    shape = getattr(obj, 'shape', None)\n",
            "            ^^^^^^^^^^^^^^^^^^^^^^^^^^^\n",
            "  File \"/usr/local/lib/python3.11/dist-packages/werkzeug/local.py\", line 318, in __get__\n",
            "    obj = instance._get_current_object()\n",
            "          ^^^^^^^^^^^^^^^^^^^^^^^^^^^^^^\n",
            "  File \"/usr/local/lib/python3.11/dist-packages/werkzeug/local.py\", line 519, in _get_current_object\n",
            "    raise RuntimeError(unbound_message) from None\n",
            "RuntimeError: Working outside of request context.\n",
            "\n",
            "This typically means that you attempted to use functionality that needed\n",
            "an active HTTP request. Consult the documentation on testing for\n",
            "information about how to avoid this problem.\n",
            "ERROR:root:Unexpected exception finding object shape\n",
            "Traceback (most recent call last):\n",
            "  File \"/usr/local/lib/python3.11/dist-packages/google/colab/_debugpy_repr.py\", line 54, in get_shape\n",
            "    shape = getattr(obj, 'shape', None)\n",
            "            ^^^^^^^^^^^^^^^^^^^^^^^^^^^\n",
            "  File \"/usr/local/lib/python3.11/dist-packages/werkzeug/local.py\", line 318, in __get__\n",
            "    obj = instance._get_current_object()\n",
            "          ^^^^^^^^^^^^^^^^^^^^^^^^^^^^^^\n",
            "  File \"/usr/local/lib/python3.11/dist-packages/werkzeug/local.py\", line 519, in _get_current_object\n",
            "    raise RuntimeError(unbound_message) from None\n",
            "RuntimeError: Working outside of request context.\n",
            "\n",
            "This typically means that you attempted to use functionality that needed\n",
            "an active HTTP request. Consult the documentation on testing for\n",
            "information about how to avoid this problem.\n",
            "ERROR:root:Unexpected exception finding object shape\n",
            "Traceback (most recent call last):\n",
            "  File \"/usr/local/lib/python3.11/dist-packages/google/colab/_debugpy_repr.py\", line 54, in get_shape\n",
            "    shape = getattr(obj, 'shape', None)\n",
            "            ^^^^^^^^^^^^^^^^^^^^^^^^^^^\n",
            "  File \"/usr/local/lib/python3.11/dist-packages/werkzeug/local.py\", line 318, in __get__\n",
            "    obj = instance._get_current_object()\n",
            "          ^^^^^^^^^^^^^^^^^^^^^^^^^^^^^^\n",
            "  File \"/usr/local/lib/python3.11/dist-packages/werkzeug/local.py\", line 519, in _get_current_object\n",
            "    raise RuntimeError(unbound_message) from None\n",
            "RuntimeError: Working outside of request context.\n",
            "\n",
            "This typically means that you attempted to use functionality that needed\n",
            "an active HTTP request. Consult the documentation on testing for\n",
            "information about how to avoid this problem.\n",
            "ERROR:root:Unexpected exception finding object shape\n",
            "Traceback (most recent call last):\n",
            "  File \"/usr/local/lib/python3.11/dist-packages/google/colab/_debugpy_repr.py\", line 54, in get_shape\n",
            "    shape = getattr(obj, 'shape', None)\n",
            "            ^^^^^^^^^^^^^^^^^^^^^^^^^^^\n",
            "  File \"/usr/local/lib/python3.11/dist-packages/werkzeug/local.py\", line 318, in __get__\n",
            "    obj = instance._get_current_object()\n",
            "          ^^^^^^^^^^^^^^^^^^^^^^^^^^^^^^\n",
            "  File \"/usr/local/lib/python3.11/dist-packages/werkzeug/local.py\", line 519, in _get_current_object\n",
            "    raise RuntimeError(unbound_message) from None\n",
            "RuntimeError: Working outside of request context.\n",
            "\n",
            "This typically means that you attempted to use functionality that needed\n",
            "an active HTTP request. Consult the documentation on testing for\n",
            "information about how to avoid this problem.\n",
            "ERROR:root:Unexpected exception finding object shape\n",
            "Traceback (most recent call last):\n",
            "  File \"/usr/local/lib/python3.11/dist-packages/google/colab/_debugpy_repr.py\", line 54, in get_shape\n",
            "    shape = getattr(obj, 'shape', None)\n",
            "            ^^^^^^^^^^^^^^^^^^^^^^^^^^^\n",
            "  File \"/usr/local/lib/python3.11/dist-packages/werkzeug/local.py\", line 318, in __get__\n",
            "    obj = instance._get_current_object()\n",
            "          ^^^^^^^^^^^^^^^^^^^^^^^^^^^^^^\n",
            "  File \"/usr/local/lib/python3.11/dist-packages/werkzeug/local.py\", line 519, in _get_current_object\n",
            "    raise RuntimeError(unbound_message) from None\n",
            "RuntimeError: Working outside of request context.\n",
            "\n",
            "This typically means that you attempted to use functionality that needed\n",
            "an active HTTP request. Consult the documentation on testing for\n",
            "information about how to avoid this problem.\n",
            "ERROR:root:Unexpected exception finding object shape\n",
            "Traceback (most recent call last):\n",
            "  File \"/usr/local/lib/python3.11/dist-packages/google/colab/_debugpy_repr.py\", line 54, in get_shape\n",
            "    shape = getattr(obj, 'shape', None)\n",
            "            ^^^^^^^^^^^^^^^^^^^^^^^^^^^\n",
            "  File \"/usr/local/lib/python3.11/dist-packages/werkzeug/local.py\", line 318, in __get__\n",
            "    obj = instance._get_current_object()\n",
            "          ^^^^^^^^^^^^^^^^^^^^^^^^^^^^^^\n",
            "  File \"/usr/local/lib/python3.11/dist-packages/werkzeug/local.py\", line 519, in _get_current_object\n",
            "    raise RuntimeError(unbound_message) from None\n",
            "RuntimeError: Working outside of request context.\n",
            "\n",
            "This typically means that you attempted to use functionality that needed\n",
            "an active HTTP request. Consult the documentation on testing for\n",
            "information about how to avoid this problem.\n",
            "ERROR:root:Unexpected exception finding object shape\n",
            "Traceback (most recent call last):\n",
            "  File \"/usr/local/lib/python3.11/dist-packages/google/colab/_debugpy_repr.py\", line 54, in get_shape\n",
            "    shape = getattr(obj, 'shape', None)\n",
            "            ^^^^^^^^^^^^^^^^^^^^^^^^^^^\n",
            "  File \"/usr/local/lib/python3.11/dist-packages/werkzeug/local.py\", line 318, in __get__\n",
            "    obj = instance._get_current_object()\n",
            "          ^^^^^^^^^^^^^^^^^^^^^^^^^^^^^^\n",
            "  File \"/usr/local/lib/python3.11/dist-packages/werkzeug/local.py\", line 519, in _get_current_object\n",
            "    raise RuntimeError(unbound_message) from None\n",
            "RuntimeError: Working outside of request context.\n",
            "\n",
            "This typically means that you attempted to use functionality that needed\n",
            "an active HTTP request. Consult the documentation on testing for\n",
            "information about how to avoid this problem.\n",
            "ERROR:root:Unexpected exception finding object shape\n",
            "Traceback (most recent call last):\n",
            "  File \"/usr/local/lib/python3.11/dist-packages/google/colab/_debugpy_repr.py\", line 54, in get_shape\n",
            "    shape = getattr(obj, 'shape', None)\n",
            "            ^^^^^^^^^^^^^^^^^^^^^^^^^^^\n",
            "  File \"/usr/local/lib/python3.11/dist-packages/werkzeug/local.py\", line 318, in __get__\n",
            "    obj = instance._get_current_object()\n",
            "          ^^^^^^^^^^^^^^^^^^^^^^^^^^^^^^\n",
            "  File \"/usr/local/lib/python3.11/dist-packages/werkzeug/local.py\", line 519, in _get_current_object\n",
            "    raise RuntimeError(unbound_message) from None\n",
            "RuntimeError: Working outside of request context.\n",
            "\n",
            "This typically means that you attempted to use functionality that needed\n",
            "an active HTTP request. Consult the documentation on testing for\n",
            "information about how to avoid this problem.\n",
            "ERROR:root:Unexpected exception finding object shape\n",
            "Traceback (most recent call last):\n",
            "  File \"/usr/local/lib/python3.11/dist-packages/google/colab/_debugpy_repr.py\", line 54, in get_shape\n",
            "    shape = getattr(obj, 'shape', None)\n",
            "            ^^^^^^^^^^^^^^^^^^^^^^^^^^^\n",
            "  File \"/usr/local/lib/python3.11/dist-packages/werkzeug/local.py\", line 318, in __get__\n",
            "    obj = instance._get_current_object()\n",
            "          ^^^^^^^^^^^^^^^^^^^^^^^^^^^^^^\n",
            "  File \"/usr/local/lib/python3.11/dist-packages/werkzeug/local.py\", line 519, in _get_current_object\n",
            "    raise RuntimeError(unbound_message) from None\n",
            "RuntimeError: Working outside of request context.\n",
            "\n",
            "This typically means that you attempted to use functionality that needed\n",
            "an active HTTP request. Consult the documentation on testing for\n",
            "information about how to avoid this problem.\n",
            "ERROR:root:Unexpected exception finding object shape\n",
            "Traceback (most recent call last):\n",
            "  File \"/usr/local/lib/python3.11/dist-packages/google/colab/_debugpy_repr.py\", line 54, in get_shape\n",
            "    shape = getattr(obj, 'shape', None)\n",
            "            ^^^^^^^^^^^^^^^^^^^^^^^^^^^\n",
            "  File \"/usr/local/lib/python3.11/dist-packages/werkzeug/local.py\", line 318, in __get__\n",
            "    obj = instance._get_current_object()\n",
            "          ^^^^^^^^^^^^^^^^^^^^^^^^^^^^^^\n",
            "  File \"/usr/local/lib/python3.11/dist-packages/werkzeug/local.py\", line 519, in _get_current_object\n",
            "    raise RuntimeError(unbound_message) from None\n",
            "RuntimeError: Working outside of request context.\n",
            "\n",
            "This typically means that you attempted to use functionality that needed\n",
            "an active HTTP request. Consult the documentation on testing for\n",
            "information about how to avoid this problem.\n",
            "ERROR:root:Unexpected exception finding object shape\n",
            "Traceback (most recent call last):\n",
            "  File \"/usr/local/lib/python3.11/dist-packages/google/colab/_debugpy_repr.py\", line 54, in get_shape\n",
            "    shape = getattr(obj, 'shape', None)\n",
            "            ^^^^^^^^^^^^^^^^^^^^^^^^^^^\n",
            "  File \"/usr/local/lib/python3.11/dist-packages/werkzeug/local.py\", line 318, in __get__\n",
            "    obj = instance._get_current_object()\n",
            "          ^^^^^^^^^^^^^^^^^^^^^^^^^^^^^^\n",
            "  File \"/usr/local/lib/python3.11/dist-packages/werkzeug/local.py\", line 519, in _get_current_object\n",
            "    raise RuntimeError(unbound_message) from None\n",
            "RuntimeError: Working outside of request context.\n",
            "\n",
            "This typically means that you attempted to use functionality that needed\n",
            "an active HTTP request. Consult the documentation on testing for\n",
            "information about how to avoid this problem.\n",
            "ERROR:root:Unexpected exception finding object shape\n",
            "Traceback (most recent call last):\n",
            "  File \"/usr/local/lib/python3.11/dist-packages/google/colab/_debugpy_repr.py\", line 54, in get_shape\n",
            "    shape = getattr(obj, 'shape', None)\n",
            "            ^^^^^^^^^^^^^^^^^^^^^^^^^^^\n",
            "  File \"/usr/local/lib/python3.11/dist-packages/werkzeug/local.py\", line 318, in __get__\n",
            "    obj = instance._get_current_object()\n",
            "          ^^^^^^^^^^^^^^^^^^^^^^^^^^^^^^\n",
            "  File \"/usr/local/lib/python3.11/dist-packages/werkzeug/local.py\", line 519, in _get_current_object\n",
            "    raise RuntimeError(unbound_message) from None\n",
            "RuntimeError: Working outside of request context.\n",
            "\n",
            "This typically means that you attempted to use functionality that needed\n",
            "an active HTTP request. Consult the documentation on testing for\n",
            "information about how to avoid this problem.\n",
            "ERROR:root:Unexpected exception finding object shape\n",
            "Traceback (most recent call last):\n",
            "  File \"/usr/local/lib/python3.11/dist-packages/google/colab/_debugpy_repr.py\", line 54, in get_shape\n",
            "    shape = getattr(obj, 'shape', None)\n",
            "            ^^^^^^^^^^^^^^^^^^^^^^^^^^^\n",
            "  File \"/usr/local/lib/python3.11/dist-packages/werkzeug/local.py\", line 318, in __get__\n",
            "    obj = instance._get_current_object()\n",
            "          ^^^^^^^^^^^^^^^^^^^^^^^^^^^^^^\n",
            "  File \"/usr/local/lib/python3.11/dist-packages/werkzeug/local.py\", line 519, in _get_current_object\n",
            "    raise RuntimeError(unbound_message) from None\n",
            "RuntimeError: Working outside of request context.\n",
            "\n",
            "This typically means that you attempted to use functionality that needed\n",
            "an active HTTP request. Consult the documentation on testing for\n",
            "information about how to avoid this problem.\n",
            "ERROR:root:Unexpected exception finding object shape\n",
            "Traceback (most recent call last):\n",
            "  File \"/usr/local/lib/python3.11/dist-packages/google/colab/_debugpy_repr.py\", line 54, in get_shape\n",
            "    shape = getattr(obj, 'shape', None)\n",
            "            ^^^^^^^^^^^^^^^^^^^^^^^^^^^\n",
            "  File \"/usr/local/lib/python3.11/dist-packages/werkzeug/local.py\", line 318, in __get__\n",
            "    obj = instance._get_current_object()\n",
            "          ^^^^^^^^^^^^^^^^^^^^^^^^^^^^^^\n",
            "  File \"/usr/local/lib/python3.11/dist-packages/werkzeug/local.py\", line 519, in _get_current_object\n",
            "    raise RuntimeError(unbound_message) from None\n",
            "RuntimeError: Working outside of request context.\n",
            "\n",
            "This typically means that you attempted to use functionality that needed\n",
            "an active HTTP request. Consult the documentation on testing for\n",
            "information about how to avoid this problem.\n",
            "ERROR:root:Unexpected exception finding object shape\n",
            "Traceback (most recent call last):\n",
            "  File \"/usr/local/lib/python3.11/dist-packages/google/colab/_debugpy_repr.py\", line 54, in get_shape\n",
            "    shape = getattr(obj, 'shape', None)\n",
            "            ^^^^^^^^^^^^^^^^^^^^^^^^^^^\n",
            "  File \"/usr/local/lib/python3.11/dist-packages/werkzeug/local.py\", line 318, in __get__\n",
            "    obj = instance._get_current_object()\n",
            "          ^^^^^^^^^^^^^^^^^^^^^^^^^^^^^^\n",
            "  File \"/usr/local/lib/python3.11/dist-packages/werkzeug/local.py\", line 519, in _get_current_object\n",
            "    raise RuntimeError(unbound_message) from None\n",
            "RuntimeError: Working outside of request context.\n",
            "\n",
            "This typically means that you attempted to use functionality that needed\n",
            "an active HTTP request. Consult the documentation on testing for\n",
            "information about how to avoid this problem.\n",
            "ERROR:root:Unexpected exception finding object shape\n",
            "Traceback (most recent call last):\n",
            "  File \"/usr/local/lib/python3.11/dist-packages/google/colab/_debugpy_repr.py\", line 54, in get_shape\n",
            "    shape = getattr(obj, 'shape', None)\n",
            "            ^^^^^^^^^^^^^^^^^^^^^^^^^^^\n",
            "  File \"/usr/local/lib/python3.11/dist-packages/werkzeug/local.py\", line 318, in __get__\n",
            "    obj = instance._get_current_object()\n",
            "          ^^^^^^^^^^^^^^^^^^^^^^^^^^^^^^\n",
            "  File \"/usr/local/lib/python3.11/dist-packages/werkzeug/local.py\", line 519, in _get_current_object\n",
            "    raise RuntimeError(unbound_message) from None\n",
            "RuntimeError: Working outside of request context.\n",
            "\n",
            "This typically means that you attempted to use functionality that needed\n",
            "an active HTTP request. Consult the documentation on testing for\n",
            "information about how to avoid this problem.\n",
            "ERROR:root:Unexpected exception finding object shape\n",
            "Traceback (most recent call last):\n",
            "  File \"/usr/local/lib/python3.11/dist-packages/google/colab/_debugpy_repr.py\", line 54, in get_shape\n",
            "    shape = getattr(obj, 'shape', None)\n",
            "            ^^^^^^^^^^^^^^^^^^^^^^^^^^^\n",
            "  File \"/usr/local/lib/python3.11/dist-packages/werkzeug/local.py\", line 318, in __get__\n",
            "    obj = instance._get_current_object()\n",
            "          ^^^^^^^^^^^^^^^^^^^^^^^^^^^^^^\n",
            "  File \"/usr/local/lib/python3.11/dist-packages/werkzeug/local.py\", line 519, in _get_current_object\n",
            "    raise RuntimeError(unbound_message) from None\n",
            "RuntimeError: Working outside of request context.\n",
            "\n",
            "This typically means that you attempted to use functionality that needed\n",
            "an active HTTP request. Consult the documentation on testing for\n",
            "information about how to avoid this problem.\n",
            "ERROR:root:Unexpected exception finding object shape\n",
            "Traceback (most recent call last):\n",
            "  File \"/usr/local/lib/python3.11/dist-packages/google/colab/_debugpy_repr.py\", line 54, in get_shape\n",
            "    shape = getattr(obj, 'shape', None)\n",
            "            ^^^^^^^^^^^^^^^^^^^^^^^^^^^\n",
            "  File \"/usr/local/lib/python3.11/dist-packages/werkzeug/local.py\", line 318, in __get__\n",
            "    obj = instance._get_current_object()\n",
            "          ^^^^^^^^^^^^^^^^^^^^^^^^^^^^^^\n",
            "  File \"/usr/local/lib/python3.11/dist-packages/werkzeug/local.py\", line 519, in _get_current_object\n",
            "    raise RuntimeError(unbound_message) from None\n",
            "RuntimeError: Working outside of request context.\n",
            "\n",
            "This typically means that you attempted to use functionality that needed\n",
            "an active HTTP request. Consult the documentation on testing for\n",
            "information about how to avoid this problem.\n",
            "ERROR:root:Unexpected exception finding object shape\n",
            "Traceback (most recent call last):\n",
            "  File \"/usr/local/lib/python3.11/dist-packages/google/colab/_debugpy_repr.py\", line 54, in get_shape\n",
            "    shape = getattr(obj, 'shape', None)\n",
            "            ^^^^^^^^^^^^^^^^^^^^^^^^^^^\n",
            "  File \"/usr/local/lib/python3.11/dist-packages/werkzeug/local.py\", line 318, in __get__\n",
            "    obj = instance._get_current_object()\n",
            "          ^^^^^^^^^^^^^^^^^^^^^^^^^^^^^^\n",
            "  File \"/usr/local/lib/python3.11/dist-packages/werkzeug/local.py\", line 519, in _get_current_object\n",
            "    raise RuntimeError(unbound_message) from None\n",
            "RuntimeError: Working outside of request context.\n",
            "\n",
            "This typically means that you attempted to use functionality that needed\n",
            "an active HTTP request. Consult the documentation on testing for\n",
            "information about how to avoid this problem.\n"
          ]
        },
        {
          "output_type": "stream",
          "name": "stdout",
          "text": [
            "\u001b[31mERROR: pip's dependency resolver does not currently take into account all the packages that are installed. This behaviour is the source of the following dependency conflicts.\n",
            "tf-keras 2.18.0 requires tensorflow<2.19,>=2.18, but you have tensorflow 2.15.1 which is incompatible.\n",
            "tensorflow-text 2.18.1 requires tensorflow<2.19,>=2.18.0, but you have tensorflow 2.15.1 which is incompatible.\u001b[0m\u001b[31m\n",
            "\u001b[0mSuccessfully installed keras-2.15.0 ml-dtypes-0.3.2 tensorboard-2.15.2 tensorflow-2.15.1 tensorflow-estimator-2.15.0 wrapt-1.14.1\n"
          ]
        },
        {
          "output_type": "display_data",
          "data": {
            "application/vnd.colab-display-data+json": {
              "pip_warning": {
                "packages": [
                  "keras",
                  "ml_dtypes",
                  "tensorflow",
                  "wrapt"
                ]
              },
              "id": "8efab716682f4ddea8f2217856e1bbc0"
            }
          },
          "metadata": {}
        }
      ]
    },
    {
      "cell_type": "code",
      "execution_count": 3,
      "metadata": {
        "colab": {
          "base_uri": "https://localhost:8080/",
          "height": 228
        },
        "id": "OFEpkr0wVjsy",
        "outputId": "782e1dea-d774-4c63-e3eb-85d8304a7bce"
      },
      "outputs": [
        {
          "output_type": "error",
          "ename": "AttributeError",
          "evalue": "module 'tensorflow.keras.layers' has no attribute 'AbstractRNNCell'",
          "traceback": [
            "\u001b[0;31m---------------------------------------------------------------------------\u001b[0m",
            "\u001b[0;31mAttributeError\u001b[0m                            Traceback (most recent call last)",
            "\u001b[0;32m<ipython-input-3-b4fa853314e7>\u001b[0m in \u001b[0;36m<cell line: 0>\u001b[0;34m()\u001b[0m\n\u001b[1;32m     25\u001b[0m     \u001b[0mRungeKutta\u001b[0m \u001b[0;34m=\u001b[0m \u001b[0;36m2\u001b[0m\u001b[0;34m\u001b[0m\u001b[0;34m\u001b[0m\u001b[0m\n\u001b[1;32m     26\u001b[0m \u001b[0;34m\u001b[0m\u001b[0m\n\u001b[0;32m---> 27\u001b[0;31m \u001b[0;32mclass\u001b[0m \u001b[0mLTCCell\u001b[0m\u001b[0;34m(\u001b[0m\u001b[0mtf\u001b[0m\u001b[0;34m.\u001b[0m\u001b[0mkeras\u001b[0m\u001b[0;34m.\u001b[0m\u001b[0mlayers\u001b[0m\u001b[0;34m.\u001b[0m\u001b[0mAbstractRNNCell\u001b[0m\u001b[0;34m)\u001b[0m\u001b[0;34m:\u001b[0m\u001b[0;34m\u001b[0m\u001b[0;34m\u001b[0m\u001b[0m\n\u001b[0m\u001b[1;32m     28\u001b[0m     def __init__(self, num_units, input_mapping=MappingType.Affine, solver=ODESolver.SemiImplicit,\n\u001b[1;32m     29\u001b[0m                  ode_solver_unfolds=6, activation=tf.nn.tanh, **kwargs):\n",
            "\u001b[0;31mAttributeError\u001b[0m: module 'tensorflow.keras.layers' has no attribute 'AbstractRNNCell'"
          ]
        }
      ],
      "source": [
        "import numpy as np\n",
        "import pandas as pd\n",
        "import yfinance as yf\n",
        "from sklearn.preprocessing import MinMaxScaler\n",
        "from sklearn.metrics import mean_squared_error, mean_absolute_error\n",
        "import tensorflow as tf\n",
        "from tensorflow.keras.models import load_model, Sequential\n",
        "from tensorflow.keras.layers import Dense, Dropout, RNN\n",
        "from keras.regularizers import L1L2\n",
        "from keras.initializers import GlorotUniform, Zeros\n",
        "\n",
        "from enum import Enum\n",
        "import matplotlib.pyplot as plt\n",
        "from flask import Flask, request, jsonify\n",
        "\n",
        "# Custom layers/classes as defined in app.py\n",
        "class MappingType(Enum):\n",
        "    Identity = 0\n",
        "    Linear = 1\n",
        "    Affine = 2\n",
        "\n",
        "class ODESolver(Enum):\n",
        "    SemiImplicit = 0\n",
        "    Explicit = 1\n",
        "    RungeKutta = 2\n",
        "\n",
        "class LTCCell(tf.keras.layers.AbstractRNNCell):\n",
        "    def __init__(self, num_units, input_mapping=MappingType.Affine, solver=ODESolver.SemiImplicit,\n",
        "                 ode_solver_unfolds=6, activation=tf.nn.tanh, **kwargs):\n",
        "        super().__init__(**kwargs)\n",
        "        self._num_units = num_units\n",
        "        self._ode_solver_unfolds = ode_solver_unfolds\n",
        "        self._solver = solver\n",
        "        self._input_mapping = input_mapping\n",
        "        self._activation = activation\n",
        "\n",
        "    @property\n",
        "    def state_size(self):\n",
        "        return self._num_units\n",
        "\n",
        "    @property\n",
        "    def output_size(self):\n",
        "        return self._num_units\n",
        "\n",
        "    def build(self, input_shape):\n",
        "        self.kernel = self.add_weight(shape=(input_shape[-1], self._num_units), initializer='glorot_uniform', name='kernel')\n",
        "        self.recurrent_kernel = self.add_weight(shape=(self._num_units, self._num_units), initializer='glorot_uniform', name='recurrent_kernel')\n",
        "        self.bias = self.add_weight(shape=(self._num_units,), initializer='zeros', name='bias')\n",
        "        self.built = True\n",
        "\n",
        "    def call(self, inputs, states):\n",
        "        prev_output = states[0]\n",
        "        net_input = tf.matmul(inputs, self.kernel)\n",
        "        net_input += tf.matmul(prev_output, self.recurrent_kernel)\n",
        "        net_input += self.bias\n",
        "        output = self._activation(net_input)\n",
        "\n",
        "        return output, [output]\n",
        "\n",
        "    def get_config(self):\n",
        "        config = super(LTCCell, self).get_config()\n",
        "        config.update({\"num_units\": self._num_units})\n",
        "        return config\n",
        "\n",
        "class CTRNN(tf.keras.layers.AbstractRNNCell):\n",
        "    def __init__(self, units, global_feedback=False, activation=tf.nn.tanh, cell_clip=None, **kwargs):\n",
        "        self.units = units\n",
        "        self.global_feedback = global_feedback\n",
        "        self.activation = activation\n",
        "        self.cell_clip = cell_clip\n",
        "        super(CTRNN, self).__init__(**kwargs)\n",
        "\n",
        "    @property\n",
        "    def state_size(self):\n",
        "        return self.units\n",
        "\n",
        "    @property\n",
        "    def output_size(self):\n",
        "        return self.units\n",
        "\n",
        "    def build(self, input_shape):\n",
        "        self.kernel = self.add_weight(shape=(input_shape[-1], self.units), initializer='glorot_uniform', name='kernel')\n",
        "        self.recurrent_kernel = self.add_weight(shape=(self.units, self.units), initializer='glorot_uniform', name='recurrent_kernel')\n",
        "        self.bias = self.add_weight(shape=(self.units,), initializer='zeros', name='bias')\n",
        "        self.built = True\n",
        "\n",
        "    def call(self, inputs, states):\n",
        "        prev_output = states[0]\n",
        "        net_input = tf.matmul(inputs, self.kernel)\n",
        "        net_input += tf.matmul(prev_output, self.recurrent_kernel)\n",
        "        net_input += self.bias\n",
        "        output = self.activation(net_input)\n",
        "\n",
        "        if self.cell_clip is not None:\n",
        "            output = tf.clip_by_value(output, -self.cell_clip, self.cell_clip)\n",
        "\n",
        "        return output, [output]\n",
        "\n",
        "class NODE(tf.keras.layers.AbstractRNNCell):\n",
        "    def __init__(self, units, cell_clip=None, **kwargs):\n",
        "        self.units = units\n",
        "        self.cell_clip = cell_clip\n",
        "        super(NODE, self).__init__(**kwargs)\n",
        "\n",
        "    @property\n",
        "    def state_size(self):\n",
        "        return self.units\n",
        "\n",
        "    @property\n",
        "    def output_size(self):\n",
        "        return self.units\n",
        "\n",
        "    def build(self, input_shape):\n",
        "        self.kernel = self.add_weight(shape=(input_shape[-1], self.units), initializer='glorot_uniform', name='kernel')\n",
        "        self.recurrent_kernel = self.add_weight(shape=(self.units, self.units), initializer='glorot_uniform', name='recurrent_kernel')\n",
        "        self.bias = self.add_weight(shape=(self.units,), initializer='zeros', name='bias')\n",
        "        self.built = True\n",
        "\n",
        "    def call(self, inputs, states):\n",
        "        prev_output = states[0]\n",
        "        net_input = tf.matmul(inputs, self.kernel)\n",
        "        net_input += tf.matmul(prev_output, self.recurrent_kernel)\n",
        "        net_input += self.bias\n",
        "        output = tf.nn.tanh(net_input)\n",
        "\n",
        "        if self.cell_clip is not None:\n",
        "            output = tf.clip_by_value(output, -self.cell_clip, self.cell_clip)\n",
        "\n",
        "        return output, [output]\n",
        "\n",
        "class CTGRU(tf.keras.layers.AbstractRNNCell):\n",
        "    def __init__(self, units, cell_clip=None, **kwargs):\n",
        "        self.units = units\n",
        "        self.cell_clip = cell_clip\n",
        "        super(CTGRU, self).__init__(**kwargs)\n",
        "\n",
        "    @property\n",
        "    def state_size(self):\n",
        "        return self.units\n",
        "\n",
        "    @property\n",
        "    def output_size(self):\n",
        "        return self.units\n",
        "\n",
        "    def build(self, input_shape):\n",
        "        self.kernel = self.add_weight(shape=(input_shape[-1], 2 * self.units), initializer='glorot_uniform', name='kernel')\n",
        "        self.recurrent_kernel = self.add_weight(shape=(self.units, 2 * self.units), initializer='glorot_uniform', name='recurrent_kernel')\n",
        "        self.bias = self.add_weight(shape=(2 * self.units,), initializer='zeros', name='bias')\n",
        "        self.kernel_c = self.add_weight(shape=(input_shape[-1], self.units), initializer='glorot_uniform', name='kernel_c')\n",
        "        self.recurrent_kernel_c = self.add_weight(shape=(self.units, self.units), initializer='glorot_uniform', name='recurrent_kernel_c')\n",
        "        self.bias_c = self.add_weight(shape=(self.units,), initializer='zeros', name='bias_c')\n",
        "        self.built = True\n",
        "\n",
        "    def call(self, inputs, states):\n",
        "        prev_output = states[0]\n",
        "        zr = tf.matmul(inputs, self.kernel)\n",
        "        zr += tf.matmul(prev_output, self.recurrent_kernel)\n",
        "        zr += self.bias\n",
        "        z, r = tf.split(zr, 2, axis=-1)\n",
        "\n",
        "        z = tf.sigmoid(z)\n",
        "        r = tf.sigmoid(r)\n",
        "\n",
        "        c = tf.matmul(inputs, self.kernel_c)\n",
        "        c += r * tf.matmul(prev_output, self.recurrent_kernel_c)\n",
        "        c += self.bias_c\n",
        "        c = tf.nn.tanh(c)\n",
        "\n",
        "        output = (1 - z) * prev_output + z * c\n",
        "\n",
        "        if self.cell_clip is not None:\n",
        "            output = tf.clip_by_value(output, -self.cell_clip, self.cell_clip)\n",
        "\n",
        "        return output, [output]\n",
        "\n",
        "input_dim = 28  # Assuming the input_dim is known\n",
        "\n",
        "# Define the model architecture\n",
        "model = Sequential()\n",
        "# Add the RNN layer with LTCCell\n",
        "model.add(RNN(LTCCell(num_units=150), input_shape=(None, input_dim), name='rnn'))\n",
        "# Add Dropout layer\n",
        "model.add(Dropout(rate=0.2, name='dropout'))\n",
        "# Add Dense layer with L1 and L2 regularizers\n",
        "model.add(Dense(\n",
        "    units=64,\n",
        "    activation='linear',\n",
        "    kernel_initializer=GlorotUniform(),\n",
        "    bias_initializer=Zeros(),\n",
        "    kernel_regularizer=L1L2(l1=9.999999747378752e-06, l2=9.999999747378752e-05),\n",
        "    bias_regularizer=L1L2(l2=9.999999747378752e-06),\n",
        "    activity_regularizer=L1L2(l1=9.999999747378752e-05),\n",
        "    name='dense'\n",
        "))\n",
        "# Add final Dense layer\n",
        "model.add(Dense(\n",
        "    units=1,\n",
        "    activation='linear',\n",
        "    kernel_initializer=GlorotUniform(),\n",
        "    bias_initializer=Zeros(),\n",
        "    name='dense_1'\n",
        "))\n",
        "\n",
        "# Compile the new model\n",
        "model.compile(optimizer='adam', loss='mean_squared_error')\n",
        "\n",
        "# Inspect the input shape of the original model\n",
        "original_input_shape = model.input_shape[1:]  # Excluding batch size\n",
        "print(f\"Original model input shape: {original_input_shape}\")\n",
        "\n",
        "# Print model summary to verify\n",
        "model.summary()\n",
        "\n",
        "# Download SPY data\n",
        "data = yf.download('SPY', start='2010-01-01', end='2024-07-01')\n",
        "# data.to_csv(f\"data.csv\")\n",
        "\n",
        "# Feature engineering function\n",
        "def feature_engineering(data):\n",
        "       # Check if data is valid and has sufficient length\n",
        "    if data is None or data.empty or len(data) < 15:\n",
        "        raise ValueError(\"Insufficient data for feature engineering\")\n",
        "\n",
        "    data['MACD_14_21_9'], data['MACDs_14_21_9'], data['MACDh_14_21_9'] = macd(data['Close'], fast=14, slow=21, signal=9)\n",
        "    data['Daily Returns'] = data['Close'].pct_change()\n",
        "    data['5-Day Momentum'] = data['Close'].diff(5)\n",
        "    data['14-Day ATR'] = atr(data)\n",
        "    data['14-Day SMA'] = data['Close'].rolling(window=14).mean()\n",
        "    data['14-Day EMA'] = data['Close'].ewm(span=14, adjust=False).mean()\n",
        "    data['14-Day RSI'] = rsi(data['Close'], window=14)\n",
        "    data['BBL_14_2.0'], data['BBM_14_2.0'], data['BBU_14_2.0'] = bollinger_bands(data['Close'], window=14, num_std=2)\n",
        "    data['BBB_14_2.0'] = data['BBU_14_2.0'] - data['BBL_14_2.0']\n",
        "    data['BBP_14_2.0'] = (data['Close'] - data['BBL_14_2.0']) / (data['BBU_14_2.0'] - data['BBL_14_2.0'])\n",
        "    data['OBV'] = obv(data)\n",
        "    data['STOCHk_14_3_3'], data['STOCHd_14_3_3'] = stochastic_oscillator(data, window=14)\n",
        "    data['STOCHk_3_3_3'], data['STOCHd_3_3_3'] = stochastic_oscillator(data, window=3)\n",
        "    data['Fib 38.2%'] = data['Close'].rolling(window=14).apply(lambda x: np.percentile(x, 38.2))\n",
        "    data['Fib 50%'] = data['Close'].rolling(window=14).apply(lambda x: np.percentile(x, 50))\n",
        "    data['Fib 61.8%'] = data['Close'].rolling(window=14).apply(lambda x: np.percentile(x, 61.8))\n",
        "    data['3 Day ROC'] = roc(data['Close'], window=3)\n",
        "    return data\n",
        "\n",
        "# Indicator functions\n",
        "def rsi(series, window):\n",
        "    delta = series.diff().dropna()\n",
        "    gain = delta.where(delta > 0, 0)\n",
        "    loss = -delta.where(delta < 0, 0)\n",
        "    avg_gain = gain.rolling(window=window, min_periods=1).mean()\n",
        "    avg_loss = loss.rolling(window=window, min_periods=1).mean()\n",
        "    rs = avg_gain / avg_loss\n",
        "    return 100 - (100 / (1 + rs))\n",
        "\n",
        "def macd(series, fast=12, slow=26, signal=9):\n",
        "    fast_ema = series.ewm(span=fast, adjust=False).mean()\n",
        "    slow_ema = series.ewm(span=slow, adjust=False).mean()\n",
        "    macd = fast_ema - slow_ema\n",
        "    signal = macd.ewm(span=signal, adjust=False).mean()\n",
        "    hist = macd - signal\n",
        "    return macd, signal, hist\n",
        "\n",
        "def atr(data, window=14):\n",
        "    high_low = data['High'] - data['Low']\n",
        "    high_close = np.abs(data['High'] - data['Close'].shift())\n",
        "    low_close = np.abs(data['Low'] - data['Close'].shift())\n",
        "    tr = high_low.combine(high_close, max).combine(low_close, max)\n",
        "    return tr.rolling(window=window, min_periods=1).mean()\n",
        "\n",
        "def bollinger_bands(series, window, num_std=2):\n",
        "    sma = series.rolling(window).mean()\n",
        "    std = series.rolling(window).std()\n",
        "    upper_band = sma + num_std * std\n",
        "    lower_band = sma - num_std * std\n",
        "    return lower_band, sma, upper_band\n",
        "\n",
        "def obv(data):\n",
        "    obv = (np.sign(data['Close'].diff()) * data['Volume']).fillna(0).cumsum()\n",
        "    return obv\n",
        "\n",
        "def stochastic_oscillator(data, window=14, smooth_window=3):\n",
        "    low_min = data['Low'].rolling(window).min()\n",
        "    high_max = data['High'].rolling(window).max()\n",
        "    k = 100 * (data['Close'] - low_min) / (high_max - low_min)\n",
        "    d = k.rolling(smooth_window).mean()\n",
        "    return k, d\n",
        "\n",
        "def roc(series, window):\n",
        "    return series.diff(window) / series.shift(window)\n",
        "\n",
        "# Apply feature engineering\n",
        "data = feature_engineering(data)\n",
        "data.dropna(inplace=True)\n",
        "# data.to_csv(f\"data.csv\")\n",
        "\n",
        "# Preprocess the data\n",
        "total_features = ['Open', 'High', 'Low', 'Close', 'Volume', 'MACD_14_21_9', 'MACDh_14_21_9', 'MACDs_14_21_9', 'Daily Returns',\n",
        "                  '5-Day Momentum', '14-Day ATR', '14-Day SMA', '14-Day EMA', '14-Day RSI', 'BBL_14_2.0', 'BBM_14_2.0',\n",
        "                  'BBU_14_2.0', 'BBB_14_2.0', 'BBP_14_2.0', 'OBV', 'STOCHk_14_3_3', 'STOCHd_14_3_3', 'STOCHk_3_3_3',\n",
        "                  'STOCHd_3_3_3', 'Fib 38.2%', 'Fib 50%', 'Fib 61.8%', '3 Day ROC']\n",
        "data = data[total_features]\n",
        "scaler = MinMaxScaler()\n",
        "scaled_data = scaler.fit_transform(data)\n",
        "\n",
        "# Create sequences\n",
        "def create_sequences(data, seq_length):\n",
        "    X = []\n",
        "    y = []\n",
        "    for i in range(seq_length, len(data)):\n",
        "        seq = data[i-seq_length:i]\n",
        "        X.append(seq)\n",
        "        y.append(data[i, 3])  # 'Close' is the target variable, which is at index 3 in the total_features list\n",
        "    return np.array(X), np.array(y)\n",
        "\n",
        "SEQ_LENGTH = 10  # Look-back period\n",
        "NUM_FEATURES = len(total_features)\n",
        "\n",
        "# Generate sequences with the additional features\n",
        "X, y = create_sequences(scaled_data, SEQ_LENGTH)\n",
        "\n",
        "# Split the data into training and testing sets\n",
        "split = int(0.8 * len(X))\n",
        "X_train, X_test = X[:split], X[split:]\n",
        "y_train, y_test = y[:split], y[split:]\n",
        "\n",
        "print(f\"Training data shape: {X_train.shape}\")\n",
        "print(f\"Testing data shape: {X_test.shape}\")\n",
        "\n",
        "# Train the new model with the SPY data\n",
        "# model.fit(X_train, y_train, epochs=50, batch_size=16, validation_data=(X_test, y_test))\n",
        "\n",
        "# Training the model and capturing the history\n",
        "history = model.fit(X_train, y_train, epochs=900, batch_size=32, validation_data=(X_test, y_test))\n",
        "\n",
        "# Save the new model\n",
        "model.save('spy_model.h5')\n",
        "\n",
        "# Evaluate the model\n",
        "test_loss = model.evaluate(X_test, y_test, verbose=0)\n",
        "Y_pred = model.predict(X_test)\n",
        "\n",
        "# Inverse transform the predictions and true values to get the actual values\n",
        "y_test_actual = scaler.inverse_transform(np.c_[np.zeros((len(y_test), NUM_FEATURES-1)), y_test])[:, -1]\n",
        "Y_pred_actual = scaler.inverse_transform(np.c_[np.zeros((len(Y_pred), NUM_FEATURES-1)), Y_pred])[:, -1]\n",
        "\n",
        "# Calculate metrics\n",
        "mse = mean_squared_error(y_test_actual, Y_pred_actual)\n",
        "rmse = np.sqrt(mse)\n",
        "mae = mean_absolute_error(y_test_actual, Y_pred_actual)\n",
        "\n",
        "print(f\"Test Loss (MSE): {test_loss:.4f}\")\n",
        "print(f\"Mean Squared Error (MSE): {mse:.4f}\")\n",
        "print(f\"Root Mean Squared Error (RMSE): {rmse:.4f}\")\n",
        "print(f\"Mean Absolute Error (MAE): {mae:.4f}\")\n",
        "\n",
        "# Plotting the training and validation loss\n",
        "plt.figure(figsize=(14, 7))\n",
        "plt.plot(history.history['loss'], label='Training loss')\n",
        "plt.plot(history.history['val_loss'], label='Validation loss')\n",
        "plt.xlabel('Epochs')\n",
        "plt.ylabel('Loss')\n",
        "plt.title('Training and Validation Loss')\n",
        "plt.legend()\n",
        "plt.show()\n",
        "\n",
        "# Plot the actual vs predicted prices\n",
        "plt.figure(figsize=(14, 7))\n",
        "plt.plot(y_test_actual, color='blue', label='Actual Price')\n",
        "plt.plot(Y_pred_actual, color='red', label='Predicted Price')\n",
        "plt.title('Actual vs Predicted Stock Price')\n",
        "plt.xlabel('Time')\n",
        "plt.ylabel('Stock Price')\n",
        "plt.legend()\n",
        "plt.show()\n",
        "\n"
      ]
    },
    {
      "cell_type": "markdown",
      "source": [
        "# 新段落"
      ],
      "metadata": {
        "id": "jd0SOJzbE-Am"
      }
    },
    {
      "cell_type": "markdown",
      "source": [
        "# 新段落"
      ],
      "metadata": {
        "id": "lH51mT1GFCS-"
      }
    }
  ],
  "metadata": {
    "colab": {
      "provenance": [],
      "include_colab_link": true
    },
    "kernelspec": {
      "display_name": "Python 3",
      "name": "python3"
    },
    "language_info": {
      "name": "python"
    }
  },
  "nbformat": 4,
  "nbformat_minor": 0
}